Traceback (most recent call last):
  File "check_return.py", line 76, in <module>
    main(sys.argv[i])
  File "check_return.py", line 22, in main
    f = open(fileName, 'r')
IOError: [Errno 2] No such file or directory: './mDNSResponder-379.38.1/mDNSMacOS9/Mac'
Traceback (most recent call last):
  File "check_return.py", line 76, in <module>
    main(sys.argv[i])
  File "check_return.py", line 22, in main
    f = open(fileName, 'r')
IOError: [Errno 2] No such file or directory: 'OS'
Traceback (most recent call last):
  File "check_return.py", line 76, in <module>
    main(sys.argv[i])
  File "check_return.py", line 22, in main
    f = open(fileName, 'r')
IOError: [Errno 2] No such file or directory: 'Test'
Traceback (most recent call last):
  File "check_return.py", line 76, in <module>
    main(sys.argv[i])
  File "check_return.py", line 22, in main
    f = open(fileName, 'r')
IOError: [Errno 2] No such file or directory: 'Responder.c'
Traceback (most recent call last):
  File "check_return.py", line 76, in <module>
    main(sys.argv[i])
  File "check_return.py", line 22, in main
    f = open(fileName, 'r')
IOError: [Errno 2] No such file or directory: './mDNSResponder-379.38.1/mDNSMacOS9/Mac'
Traceback (most recent call last):
  File "check_return.py", line 76, in <module>
    main(sys.argv[i])
  File "check_return.py", line 22, in main
    f = open(fileName, 'r')
IOError: [Errno 2] No such file or directory: 'OS'
Traceback (most recent call last):
  File "check_return.py", line 76, in <module>
    main(sys.argv[i])
  File "check_return.py", line 22, in main
    f = open(fileName, 'r')
IOError: [Errno 2] No such file or directory: 'Test'
Traceback (most recent call last):
  File "check_return.py", line 76, in <module>
    main(sys.argv[i])
  File "check_return.py", line 22, in main
    f = open(fileName, 'r')
IOError: [Errno 2] No such file or directory: 'Searcher.c'
Traceback (most recent call last):
  File "check_return.py", line 76, in <module>
    main(sys.argv[i])
  File "check_return.py", line 22, in main
    f = open(fileName, 'r')
IOError: [Errno 2] No such file or directory: './IOSCSIParallelFamily-251.0.2/TestTools/SCSITargetProber/Common'
Traceback (most recent call last):
  File "check_return.py", line 76, in <module>
    main(sys.argv[i])
  File "check_return.py", line 22, in main
    f = open(fileName, 'r')
IOError: [Errno 2] No such file or directory: 'Code/Probing.c'
Traceback (most recent call last):
  File "check_return.py", line 76, in <module>
    main(sys.argv[i])
  File "check_return.py", line 22, in main
    f = open(fileName, 'r')
IOError: [Errno 2] No such file or directory: './IOUSBFamily-630.4.5/Examples/USBSimple'
Traceback (most recent call last):
  File "check_return.py", line 76, in <module>
    main(sys.argv[i])
  File "check_return.py", line 22, in main
    f = open(fileName, 'r')
IOError: [Errno 2] No such file or directory: 'Example/main.c'
Traceback (most recent call last):
  File "check_return.py", line 76, in <module>
    main(sys.argv[i])
  File "check_return.py", line 22, in main
    f = open(fileName, 'r')
IOError: [Errno 2] No such file or directory: './IOUSBFamily-630.4.5/Examples/Deva'
Traceback (most recent call last):
  File "check_return.py", line 76, in <module>
    main(sys.argv[i])
  File "check_return.py", line 22, in main
    f = open(fileName, 'r')
IOError: [Errno 2] No such file or directory: 'Example/deva.c'
Traceback (most recent call last):
  File "check_return.py", line 76, in <module>
    main(sys.argv[i])
  File "check_return.py", line 22, in main
    f = open(fileName, 'r')
IOError: [Errno 2] No such file or directory: './IOUSBFamily-630.4.5/Examples/Deva'
Traceback (most recent call last):
  File "check_return.py", line 76, in <module>
    main(sys.argv[i])
  File "check_return.py", line 22, in main
    f = open(fileName, 'r')
IOError: [Errno 2] No such file or directory: 'Example/something.c'
Traceback (most recent call last):
  File "check_return.py", line 76, in <module>
    main(sys.argv[i])
  File "check_return.py", line 22, in main
    f = open(fileName, 'r')
IOError: [Errno 2] No such file or directory: './IOUSBFamily-630.4.5/Examples/Deva'
Traceback (most recent call last):
  File "check_return.py", line 76, in <module>
    main(sys.argv[i])
  File "check_return.py", line 22, in main
    f = open(fileName, 'r')
IOError: [Errno 2] No such file or directory: 'Example/main.c'
Traceback (most recent call last):
  File "check_return.py", line 76, in <module>
    main(sys.argv[i])
  File "check_return.py", line 22, in main
    f = open(fileName, 'r')
IOError: [Errno 2] No such file or directory: './IOUSBFamily-630.4.5/Examples/Deva'
Traceback (most recent call last):
  File "check_return.py", line 76, in <module>
    main(sys.argv[i])
  File "check_return.py", line 22, in main
    f = open(fileName, 'r')
IOError: [Errno 2] No such file or directory: 'Example/printInterpretedError.c'
Traceback (most recent call last):
  File "check_return.py", line 76, in <module>
    main(sys.argv[i])
  File "check_return.py", line 22, in main
    f = open(fileName, 'r')
IOError: [Errno 2] No such file or directory: './IOUSBFamily-630.4.5/Examples/AnchorUSB'
Traceback (most recent call last):
  File "check_return.py", line 76, in <module>
    main(sys.argv[i])
  File "check_return.py", line 22, in main
    f = open(fileName, 'r')
IOError: [Errno 2] No such file or directory: 'Driver/demotonehex.c'
Traceback (most recent call last):
  File "check_return.py", line 76, in <module>
    main(sys.argv[i])
  File "check_return.py", line 22, in main
    f = open(fileName, 'r')
IOError: [Errno 2] No such file or directory: './IOUSBFamily-630.4.5/Examples/Another'
Traceback (most recent call last):
  File "check_return.py", line 76, in <module>
    main(sys.argv[i])
  File "check_return.py", line 22, in main
    f = open(fileName, 'r')
IOError: [Errno 2] No such file or directory: 'USB'
Traceback (most recent call last):
  File "check_return.py", line 76, in <module>
    main(sys.argv[i])
  File "check_return.py", line 22, in main
    f = open(fileName, 'r')
IOError: [Errno 2] No such file or directory: 'Notification'
Traceback (most recent call last):
  File "check_return.py", line 76, in <module>
    main(sys.argv[i])
  File "check_return.py", line 22, in main
    f = open(fileName, 'r')
IOError: [Errno 2] No such file or directory: 'Example/USBNotificationExample.c'
Traceback (most recent call last):
  File "check_return.py", line 76, in <module>
    main(sys.argv[i])
  File "check_return.py", line 22, in main
    f = open(fileName, 'r')
IOError: [Errno 2] No such file or directory: './IOUSBFamily-630.4.5/Examples/USBNotification'
Traceback (most recent call last):
  File "check_return.py", line 76, in <module>
    main(sys.argv[i])
  File "check_return.py", line 22, in main
    f = open(fileName, 'r')
IOError: [Errno 2] No such file or directory: 'Example/bulktest.c'
Traceback (most recent call last):
  File "check_return.py", line 76, in <module>
    main(sys.argv[i])
  File "check_return.py", line 22, in main
    f = open(fileName, 'r')
IOError: [Errno 2] No such file or directory: './IOUSBFamily-630.4.5/Examples/USBNotification'
Traceback (most recent call last):
  File "check_return.py", line 76, in <module>
    main(sys.argv[i])
  File "check_return.py", line 22, in main
    f = open(fileName, 'r')
IOError: [Errno 2] No such file or directory: 'Example/main.c'
Traceback (most recent call last):
  File "check_return.py", line 76, in <module>
    main(sys.argv[i])
  File "check_return.py", line 22, in main
    f = open(fileName, 'r')
IOError: [Errno 2] No such file or directory: './IOUSBFamily-630.4.5/Examples/Ezloader'
Traceback (most recent call last):
  File "check_return.py", line 76, in <module>
    main(sys.argv[i])
  File "check_return.py", line 22, in main
    f = open(fileName, 'r')
IOError: [Errno 2] No such file or directory: 'Example/main.c'
Traceback (most recent call last):
  File "check_bad_words.py", line 47, in <module>
    main(sys.argv[i])
  File "check_bad_words.py", line 21, in main
    f = open(fileName, 'r')
IOError: [Errno 2] No such file or directory: './mDNSResponder-379.38.1/mDNSMacOS9/Mac'
Traceback (most recent call last):
  File "check_bad_words.py", line 47, in <module>
    main(sys.argv[i])
  File "check_bad_words.py", line 21, in main
    f = open(fileName, 'r')
IOError: [Errno 2] No such file or directory: 'OS'
Traceback (most recent call last):
  File "check_bad_words.py", line 47, in <module>
    main(sys.argv[i])
  File "check_bad_words.py", line 21, in main
    f = open(fileName, 'r')
IOError: [Errno 2] No such file or directory: 'Test'
Traceback (most recent call last):
  File "check_bad_words.py", line 47, in <module>
    main(sys.argv[i])
  File "check_bad_words.py", line 21, in main
    f = open(fileName, 'r')
IOError: [Errno 2] No such file or directory: 'Responder.c'
Traceback (most recent call last):
  File "check_bad_words.py", line 47, in <module>
    main(sys.argv[i])
  File "check_bad_words.py", line 21, in main
    f = open(fileName, 'r')
IOError: [Errno 2] No such file or directory: './mDNSResponder-379.38.1/mDNSMacOS9/Mac'
Traceback (most recent call last):
  File "check_bad_words.py", line 47, in <module>
    main(sys.argv[i])
  File "check_bad_words.py", line 21, in main
    f = open(fileName, 'r')
IOError: [Errno 2] No such file or directory: 'OS'
Traceback (most recent call last):
  File "check_bad_words.py", line 47, in <module>
    main(sys.argv[i])
  File "check_bad_words.py", line 21, in main
    f = open(fileName, 'r')
IOError: [Errno 2] No such file or directory: 'Test'
Traceback (most recent call last):
  File "check_bad_words.py", line 47, in <module>
    main(sys.argv[i])
  File "check_bad_words.py", line 21, in main
    f = open(fileName, 'r')
IOError: [Errno 2] No such file or directory: 'Searcher.c'
Traceback (most recent call last):
  File "check_bad_words.py", line 47, in <module>
    main(sys.argv[i])
  File "check_bad_words.py", line 21, in main
    f = open(fileName, 'r')
IOError: [Errno 2] No such file or directory: './IOSCSIParallelFamily-251.0.2/TestTools/SCSITargetProber/Common'
Traceback (most recent call last):
  File "check_bad_words.py", line 47, in <module>
    main(sys.argv[i])
  File "check_bad_words.py", line 21, in main
    f = open(fileName, 'r')
IOError: [Errno 2] No such file or directory: 'Code/Probing.c'
Traceback (most recent call last):
  File "check_bad_words.py", line 47, in <module>
    main(sys.argv[i])
  File "check_bad_words.py", line 21, in main
    f = open(fileName, 'r')
IOError: [Errno 2] No such file or directory: './IOUSBFamily-630.4.5/Examples/USBSimple'
Traceback (most recent call last):
  File "check_bad_words.py", line 47, in <module>
    main(sys.argv[i])
  File "check_bad_words.py", line 21, in main
    f = open(fileName, 'r')
IOError: [Errno 2] No such file or directory: 'Example/main.c'
Traceback (most recent call last):
  File "check_bad_words.py", line 47, in <module>
    main(sys.argv[i])
  File "check_bad_words.py", line 21, in main
    f = open(fileName, 'r')
IOError: [Errno 2] No such file or directory: './IOUSBFamily-630.4.5/Examples/Deva'
Traceback (most recent call last):
  File "check_bad_words.py", line 47, in <module>
    main(sys.argv[i])
  File "check_bad_words.py", line 21, in main
    f = open(fileName, 'r')
IOError: [Errno 2] No such file or directory: 'Example/deva.c'
Traceback (most recent call last):
  File "check_bad_words.py", line 47, in <module>
    main(sys.argv[i])
  File "check_bad_words.py", line 21, in main
    f = open(fileName, 'r')
IOError: [Errno 2] No such file or directory: './IOUSBFamily-630.4.5/Examples/Deva'
Traceback (most recent call last):
  File "check_bad_words.py", line 47, in <module>
    main(sys.argv[i])
  File "check_bad_words.py", line 21, in main
    f = open(fileName, 'r')
IOError: [Errno 2] No such file or directory: 'Example/something.c'
Traceback (most recent call last):
  File "check_bad_words.py", line 47, in <module>
    main(sys.argv[i])
  File "check_bad_words.py", line 21, in main
    f = open(fileName, 'r')
IOError: [Errno 2] No such file or directory: './IOUSBFamily-630.4.5/Examples/Deva'
Traceback (most recent call last):
  File "check_bad_words.py", line 47, in <module>
    main(sys.argv[i])
  File "check_bad_words.py", line 21, in main
    f = open(fileName, 'r')
IOError: [Errno 2] No such file or directory: 'Example/main.c'
Traceback (most recent call last):
  File "check_bad_words.py", line 47, in <module>
    main(sys.argv[i])
  File "check_bad_words.py", line 21, in main
    f = open(fileName, 'r')
IOError: [Errno 2] No such file or directory: './IOUSBFamily-630.4.5/Examples/Deva'
Traceback (most recent call last):
  File "check_bad_words.py", line 47, in <module>
    main(sys.argv[i])
  File "check_bad_words.py", line 21, in main
    f = open(fileName, 'r')
IOError: [Errno 2] No such file or directory: 'Example/printInterpretedError.c'
Traceback (most recent call last):
  File "check_bad_words.py", line 47, in <module>
    main(sys.argv[i])
  File "check_bad_words.py", line 21, in main
    f = open(fileName, 'r')
IOError: [Errno 2] No such file or directory: './IOUSBFamily-630.4.5/Examples/AnchorUSB'
Traceback (most recent call last):
  File "check_bad_words.py", line 47, in <module>
    main(sys.argv[i])
  File "check_bad_words.py", line 21, in main
    f = open(fileName, 'r')
IOError: [Errno 2] No such file or directory: 'Driver/demotonehex.c'
Traceback (most recent call last):
  File "check_bad_words.py", line 47, in <module>
    main(sys.argv[i])
  File "check_bad_words.py", line 21, in main
    f = open(fileName, 'r')
IOError: [Errno 2] No such file or directory: './IOUSBFamily-630.4.5/Examples/Another'
Traceback (most recent call last):
  File "check_bad_words.py", line 47, in <module>
    main(sys.argv[i])
  File "check_bad_words.py", line 21, in main
    f = open(fileName, 'r')
IOError: [Errno 2] No such file or directory: 'USB'
Traceback (most recent call last):
  File "check_bad_words.py", line 47, in <module>
    main(sys.argv[i])
  File "check_bad_words.py", line 21, in main
    f = open(fileName, 'r')
IOError: [Errno 2] No such file or directory: 'Notification'
Traceback (most recent call last):
  File "check_bad_words.py", line 47, in <module>
    main(sys.argv[i])
  File "check_bad_words.py", line 21, in main
    f = open(fileName, 'r')
IOError: [Errno 2] No such file or directory: 'Example/USBNotificationExample.c'
Traceback (most recent call last):
  File "check_bad_words.py", line 47, in <module>
    main(sys.argv[i])
  File "check_bad_words.py", line 21, in main
    f = open(fileName, 'r')
IOError: [Errno 2] No such file or directory: './IOUSBFamily-630.4.5/Examples/USBNotification'
Traceback (most recent call last):
  File "check_bad_words.py", line 47, in <module>
    main(sys.argv[i])
  File "check_bad_words.py", line 21, in main
    f = open(fileName, 'r')
IOError: [Errno 2] No such file or directory: 'Example/bulktest.c'
Traceback (most recent call last):
  File "check_bad_words.py", line 47, in <module>
    main(sys.argv[i])
  File "check_bad_words.py", line 21, in main
    f = open(fileName, 'r')
IOError: [Errno 2] No such file or directory: './IOUSBFamily-630.4.5/Examples/USBNotification'
Traceback (most recent call last):
  File "check_bad_words.py", line 47, in <module>
    main(sys.argv[i])
  File "check_bad_words.py", line 21, in main
    f = open(fileName, 'r')
IOError: [Errno 2] No such file or directory: 'Example/main.c'
Traceback (most recent call last):
  File "check_bad_words.py", line 47, in <module>
    main(sys.argv[i])
  File "check_bad_words.py", line 21, in main
    f = open(fileName, 'r')
IOError: [Errno 2] No such file or directory: './IOUSBFamily-630.4.5/Examples/Ezloader'
Traceback (most recent call last):
  File "check_bad_words.py", line 47, in <module>
    main(sys.argv[i])
  File "check_bad_words.py", line 21, in main
    f = open(fileName, 'r')
IOError: [Errno 2] No such file or directory: 'Example/main.c'
