Traceback (most recent call last):
  File "check_exec.py", line 166, in <module>
    main(sys.argv[i])
  File "check_exec.py", line 83, in main
    result = find_bounds_issues(line, argument)
  File "check_exec.py", line 94, in find_bounds_issues
    frontHalf, backHalf = line.split(variable, 1)
ValueError: empty separator
Traceback (most recent call last):
  File "check_exec.py", line 166, in <module>
    main(sys.argv[i])
  File "check_exec.py", line 83, in main
    result = find_bounds_issues(line, argument)
  File "check_exec.py", line 94, in find_bounds_issues
    frontHalf, backHalf = line.split(variable, 1)
ValueError: empty separator
Traceback (most recent call last):
  File "check_exec.py", line 166, in <module>
    main(sys.argv[i])
  File "check_exec.py", line 83, in main
    result = find_bounds_issues(line, argument)
  File "check_exec.py", line 94, in find_bounds_issues
    frontHalf, backHalf = line.split(variable, 1)
ValueError: empty separator
Traceback (most recent call last):
  File "check_exec.py", line 166, in <module>
    main(sys.argv[i])
  File "check_exec.py", line 83, in main
    result = find_bounds_issues(line, argument)
  File "check_exec.py", line 94, in find_bounds_issues
    frontHalf, backHalf = line.split(variable, 1)
ValueError: empty separator
Traceback (most recent call last):
  File "check_exec.py", line 166, in <module>
    main(sys.argv[i])
  File "check_exec.py", line 83, in main
    result = find_bounds_issues(line, argument)
  File "check_exec.py", line 94, in find_bounds_issues
    frontHalf, backHalf = line.split(variable, 1)
ValueError: empty separator
Traceback (most recent call last):
  File "check_exec.py", line 166, in <module>
    main(sys.argv[i])
  File "check_exec.py", line 83, in main
    result = find_bounds_issues(line, argument)
  File "check_exec.py", line 94, in find_bounds_issues
    frontHalf, backHalf = line.split(variable, 1)
ValueError: empty separator
Traceback (most recent call last):
  File "check_exec.py", line 166, in <module>
    main(sys.argv[i])
  File "check_exec.py", line 83, in main
    result = find_bounds_issues(line, argument)
  File "check_exec.py", line 94, in find_bounds_issues
    frontHalf, backHalf = line.split(variable, 1)
ValueError: empty separator
Traceback (most recent call last):
  File "check_exec.py", line 166, in <module>
    main(sys.argv[i])
  File "check_exec.py", line 33, in main
    for lineNum, line in enumerate(f):
  File "/usr/lib/python3.4/codecs.py", line 319, in decode
    (result, consumed) = self._buffer_decode(data, self.errors, final)
UnicodeDecodeError: 'utf-8' codec can't decode byte 0xa5 in position 3700: invalid start byte
Traceback (most recent call last):
  File "check_exec.py", line 166, in <module>
    main(sys.argv[i])
  File "check_exec.py", line 33, in main
    for lineNum, line in enumerate(f):
  File "/usr/lib/python3.4/codecs.py", line 319, in decode
    (result, consumed) = self._buffer_decode(data, self.errors, final)
UnicodeDecodeError: 'utf-8' codec can't decode byte 0xa5 in position 3616: invalid start byte
Traceback (most recent call last):
  File "check_exec.py", line 166, in <module>
    main(sys.argv[i])
  File "check_exec.py", line 83, in main
    result = find_bounds_issues(line, argument)
  File "check_exec.py", line 94, in find_bounds_issues
    frontHalf, backHalf = line.split(variable, 1)
ValueError: empty separator
Traceback (most recent call last):
  File "check_exec.py", line 166, in <module>
    main(sys.argv[i])
  File "check_exec.py", line 83, in main
    result = find_bounds_issues(line, argument)
  File "check_exec.py", line 94, in find_bounds_issues
    frontHalf, backHalf = line.split(variable, 1)
ValueError: empty separator
Traceback (most recent call last):
  File "check_exec.py", line 166, in <module>
    main(sys.argv[i])
  File "check_exec.py", line 83, in main
    result = find_bounds_issues(line, argument)
  File "check_exec.py", line 94, in find_bounds_issues
    frontHalf, backHalf = line.split(variable, 1)
ValueError: empty separator
Traceback (most recent call last):
  File "check_exec.py", line 166, in <module>
    main(sys.argv[i])
  File "check_exec.py", line 83, in main
    result = find_bounds_issues(line, argument)
  File "check_exec.py", line 94, in find_bounds_issues
    frontHalf, backHalf = line.split(variable, 1)
ValueError: empty separator
Traceback (most recent call last):
  File "check_exec.py", line 166, in <module>
    main(sys.argv[i])
  File "check_exec.py", line 83, in main
    result = find_bounds_issues(line, argument)
  File "check_exec.py", line 94, in find_bounds_issues
    frontHalf, backHalf = line.split(variable, 1)
ValueError: empty separator
Traceback (most recent call last):
  File "check_exec.py", line 166, in <module>
    main(sys.argv[i])
  File "check_exec.py", line 83, in main
    result = find_bounds_issues(line, argument)
  File "check_exec.py", line 94, in find_bounds_issues
    frontHalf, backHalf = line.split(variable, 1)
ValueError: empty separator
Traceback (most recent call last):
  File "check_exec.py", line 166, in <module>
    main(sys.argv[i])
  File "check_exec.py", line 83, in main
    result = find_bounds_issues(line, argument)
  File "check_exec.py", line 94, in find_bounds_issues
    frontHalf, backHalf = line.split(variable, 1)
ValueError: empty separator
Traceback (most recent call last):
  File "check_exec.py", line 166, in <module>
    main(sys.argv[i])
  File "check_exec.py", line 83, in main
    result = find_bounds_issues(line, argument)
  File "check_exec.py", line 94, in find_bounds_issues
    frontHalf, backHalf = line.split(variable, 1)
ValueError: empty separator
Traceback (most recent call last):
  File "check_exec.py", line 166, in <module>
    main(sys.argv[i])
  File "check_exec.py", line 83, in main
    result = find_bounds_issues(line, argument)
  File "check_exec.py", line 94, in find_bounds_issues
    frontHalf, backHalf = line.split(variable, 1)
ValueError: empty separator
Traceback (most recent call last):
  File "check_exec.py", line 166, in <module>
    main(sys.argv[i])
  File "check_exec.py", line 83, in main
    result = find_bounds_issues(line, argument)
  File "check_exec.py", line 94, in find_bounds_issues
    frontHalf, backHalf = line.split(variable, 1)
ValueError: empty separator
Traceback (most recent call last):
  File "check_exec.py", line 166, in <module>
    main(sys.argv[i])
  File "check_exec.py", line 83, in main
    result = find_bounds_issues(line, argument)
  File "check_exec.py", line 94, in find_bounds_issues
    frontHalf, backHalf = line.split(variable, 1)
ValueError: empty separator
Traceback (most recent call last):
  File "check_exec.py", line 166, in <module>
    main(sys.argv[i])
  File "check_exec.py", line 33, in main
    for lineNum, line in enumerate(f):
  File "/usr/lib/python3.4/codecs.py", line 319, in decode
    (result, consumed) = self._buffer_decode(data, self.errors, final)
UnicodeDecodeError: 'utf-8' codec can't decode byte 0xa9 in position 16: invalid start byte
Traceback (most recent call last):
  File "check_exec.py", line 166, in <module>
    main(sys.argv[i])
  File "check_exec.py", line 33, in main
    for lineNum, line in enumerate(f):
  File "/usr/lib/python3.4/codecs.py", line 319, in decode
    (result, consumed) = self._buffer_decode(data, self.errors, final)
UnicodeDecodeError: 'utf-8' codec can't decode byte 0xa9 in position 16: invalid start byte
Traceback (most recent call last):
  File "check_exec.py", line 166, in <module>
    main(sys.argv[i])
  File "check_exec.py", line 33, in main
    for lineNum, line in enumerate(f):
  File "/usr/lib/python3.4/codecs.py", line 319, in decode
    (result, consumed) = self._buffer_decode(data, self.errors, final)
UnicodeDecodeError: 'utf-8' codec can't decode byte 0xa9 in position 16: invalid start byte
Traceback (most recent call last):
  File "check_exec.py", line 166, in <module>
    main(sys.argv[i])
  File "check_exec.py", line 33, in main
    for lineNum, line in enumerate(f):
  File "/usr/lib/python3.4/codecs.py", line 319, in decode
    (result, consumed) = self._buffer_decode(data, self.errors, final)
UnicodeDecodeError: 'utf-8' codec can't decode byte 0xa9 in position 16: invalid start byte
Traceback (most recent call last):
  File "check_exec.py", line 166, in <module>
    main(sys.argv[i])
  File "check_exec.py", line 33, in main
    for lineNum, line in enumerate(f):
  File "/usr/lib/python3.4/codecs.py", line 319, in decode
    (result, consumed) = self._buffer_decode(data, self.errors, final)
UnicodeDecodeError: 'utf-8' codec can't decode byte 0xa9 in position 1134: invalid start byte
Traceback (most recent call last):
  File "check_exec.py", line 166, in <module>
    main(sys.argv[i])
  File "check_exec.py", line 33, in main
    for lineNum, line in enumerate(f):
  File "/usr/lib/python3.4/codecs.py", line 319, in decode
    (result, consumed) = self._buffer_decode(data, self.errors, final)
UnicodeDecodeError: 'utf-8' codec can't decode byte 0xc9 in position 6692: invalid continuation byte
Traceback (most recent call last):
  File "check_exec.py", line 166, in <module>
    main(sys.argv[i])
  File "check_exec.py", line 33, in main
    for lineNum, line in enumerate(f):
  File "/usr/lib/python3.4/codecs.py", line 319, in decode
    (result, consumed) = self._buffer_decode(data, self.errors, final)
UnicodeDecodeError: 'utf-8' codec can't decode byte 0xa9 in position 1217: invalid start byte
Traceback (most recent call last):
  File "check_exec.py", line 166, in <module>
    main(sys.argv[i])
  File "check_exec.py", line 33, in main
    for lineNum, line in enumerate(f):
  File "/usr/lib/python3.4/codecs.py", line 319, in decode
    (result, consumed) = self._buffer_decode(data, self.errors, final)
UnicodeDecodeError: 'utf-8' codec can't decode byte 0xa9 in position 1232: invalid start byte
Traceback (most recent call last):
  File "check_exec.py", line 166, in <module>
    main(sys.argv[i])
  File "check_exec.py", line 33, in main
    for lineNum, line in enumerate(f):
  File "/usr/lib/python3.4/codecs.py", line 319, in decode
    (result, consumed) = self._buffer_decode(data, self.errors, final)
UnicodeDecodeError: 'utf-8' codec can't decode byte 0xa9 in position 1147: invalid start byte
Traceback (most recent call last):
  File "check_exec.py", line 166, in <module>
    main(sys.argv[i])
  File "check_exec.py", line 33, in main
    for lineNum, line in enumerate(f):
  File "/usr/lib/python3.4/codecs.py", line 319, in decode
    (result, consumed) = self._buffer_decode(data, self.errors, final)
UnicodeDecodeError: 'utf-8' codec can't decode byte 0xa9 in position 1166: invalid start byte
Traceback (most recent call last):
  File "check_exec.py", line 166, in <module>
    main(sys.argv[i])
  File "check_exec.py", line 33, in main
    for lineNum, line in enumerate(f):
  File "/usr/lib/python3.4/codecs.py", line 319, in decode
    (result, consumed) = self._buffer_decode(data, self.errors, final)
UnicodeDecodeError: 'utf-8' codec can't decode byte 0xa9 in position 1162: invalid start byte
Traceback (most recent call last):
  File "check_exec.py", line 166, in <module>
    main(sys.argv[i])
  File "check_exec.py", line 33, in main
    for lineNum, line in enumerate(f):
  File "/usr/lib/python3.4/codecs.py", line 319, in decode
    (result, consumed) = self._buffer_decode(data, self.errors, final)
UnicodeDecodeError: 'utf-8' codec can't decode byte 0xa9 in position 1241: invalid start byte
Traceback (most recent call last):
  File "check_exec.py", line 166, in <module>
    main(sys.argv[i])
  File "check_exec.py", line 33, in main
    for lineNum, line in enumerate(f):
  File "/usr/lib/python3.4/codecs.py", line 319, in decode
    (result, consumed) = self._buffer_decode(data, self.errors, final)
UnicodeDecodeError: 'utf-8' codec can't decode byte 0xa9 in position 1139: invalid start byte
Traceback (most recent call last):
  File "check_exec.py", line 166, in <module>
    main(sys.argv[i])
  File "check_exec.py", line 33, in main
    for lineNum, line in enumerate(f):
  File "/usr/lib/python3.4/codecs.py", line 319, in decode
    (result, consumed) = self._buffer_decode(data, self.errors, final)
UnicodeDecodeError: 'utf-8' codec can't decode byte 0xa9 in position 1232: invalid start byte
Traceback (most recent call last):
  File "check_exec.py", line 166, in <module>
    main(sys.argv[i])
  File "check_exec.py", line 33, in main
    for lineNum, line in enumerate(f):
  File "/usr/lib/python3.4/codecs.py", line 319, in decode
    (result, consumed) = self._buffer_decode(data, self.errors, final)
UnicodeDecodeError: 'utf-8' codec can't decode byte 0xa9 in position 1145: invalid start byte
Traceback (most recent call last):
  File "check_exec.py", line 166, in <module>
    main(sys.argv[i])
  File "check_exec.py", line 33, in main
    for lineNum, line in enumerate(f):
  File "/usr/lib/python3.4/codecs.py", line 319, in decode
    (result, consumed) = self._buffer_decode(data, self.errors, final)
UnicodeDecodeError: 'utf-8' codec can't decode byte 0x80 in position 4329: invalid start byte
Traceback (most recent call last):
  File "check_exec.py", line 166, in <module>
    main(sys.argv[i])
  File "check_exec.py", line 33, in main
    for lineNum, line in enumerate(f):
  File "/usr/lib/python3.4/codecs.py", line 319, in decode
    (result, consumed) = self._buffer_decode(data, self.errors, final)
UnicodeDecodeError: 'utf-8' codec can't decode byte 0xd1 in position 5648: invalid continuation byte
Traceback (most recent call last):
  File "check_exec.py", line 166, in <module>
    main(sys.argv[i])
  File "check_exec.py", line 33, in main
    for lineNum, line in enumerate(f):
  File "/usr/lib/python3.4/codecs.py", line 319, in decode
    (result, consumed) = self._buffer_decode(data, self.errors, final)
UnicodeDecodeError: 'utf-8' codec can't decode byte 0xa9 in position 1234: invalid start byte
Traceback (most recent call last):
  File "check_exec.py", line 166, in <module>
    main(sys.argv[i])
  File "check_exec.py", line 33, in main
    for lineNum, line in enumerate(f):
  File "/usr/lib/python3.4/codecs.py", line 319, in decode
    (result, consumed) = self._buffer_decode(data, self.errors, final)
UnicodeDecodeError: 'utf-8' codec can't decode byte 0xa9 in position 1236: invalid start byte
Traceback (most recent call last):
  File "check_exec.py", line 166, in <module>
    main(sys.argv[i])
  File "check_exec.py", line 33, in main
    for lineNum, line in enumerate(f):
  File "/usr/lib/python3.4/codecs.py", line 319, in decode
    (result, consumed) = self._buffer_decode(data, self.errors, final)
UnicodeDecodeError: 'utf-8' codec can't decode byte 0xa9 in position 1147: invalid start byte
Traceback (most recent call last):
  File "check_exec.py", line 166, in <module>
    main(sys.argv[i])
  File "check_exec.py", line 33, in main
    for lineNum, line in enumerate(f):
  File "/usr/lib/python3.4/codecs.py", line 319, in decode
    (result, consumed) = self._buffer_decode(data, self.errors, final)
UnicodeDecodeError: 'utf-8' codec can't decode byte 0xa9 in position 1221: invalid start byte
Traceback (most recent call last):
  File "check_exec.py", line 166, in <module>
    main(sys.argv[i])
  File "check_exec.py", line 33, in main
    for lineNum, line in enumerate(f):
  File "/usr/lib/python3.4/codecs.py", line 319, in decode
    (result, consumed) = self._buffer_decode(data, self.errors, final)
UnicodeDecodeError: 'utf-8' codec can't decode byte 0xd2 in position 511: invalid continuation byte
Traceback (most recent call last):
  File "check_exec.py", line 166, in <module>
    main(sys.argv[i])
  File "check_exec.py", line 83, in main
    result = find_bounds_issues(line, argument)
  File "check_exec.py", line 94, in find_bounds_issues
    frontHalf, backHalf = line.split(variable, 1)
ValueError: empty separator
Traceback (most recent call last):
  File "check_exec.py", line 166, in <module>
    main(sys.argv[i])
  File "check_exec.py", line 83, in main
    result = find_bounds_issues(line, argument)
  File "check_exec.py", line 94, in find_bounds_issues
    frontHalf, backHalf = line.split(variable, 1)
ValueError: empty separator
Traceback (most recent call last):
  File "check_exec.py", line 166, in <module>
    main(sys.argv[i])
  File "check_exec.py", line 83, in main
    result = find_bounds_issues(line, argument)
  File "check_exec.py", line 94, in find_bounds_issues
    frontHalf, backHalf = line.split(variable, 1)
ValueError: empty separator
Traceback (most recent call last):
  File "check_exec.py", line 166, in <module>
    main(sys.argv[i])
  File "check_exec.py", line 83, in main
    result = find_bounds_issues(line, argument)
  File "check_exec.py", line 94, in find_bounds_issues
    frontHalf, backHalf = line.split(variable, 1)
ValueError: empty separator
Traceback (most recent call last):
  File "check_exec.py", line 166, in <module>
    main(sys.argv[i])
  File "check_exec.py", line 33, in main
    for lineNum, line in enumerate(f):
  File "/usr/lib/python3.4/codecs.py", line 319, in decode
    (result, consumed) = self._buffer_decode(data, self.errors, final)
UnicodeDecodeError: 'utf-8' codec can't decode byte 0xe4 in position 2996: invalid continuation byte
Traceback (most recent call last):
  File "check_exec.py", line 166, in <module>
    main(sys.argv[i])
  File "check_exec.py", line 83, in main
    result = find_bounds_issues(line, argument)
  File "check_exec.py", line 94, in find_bounds_issues
    frontHalf, backHalf = line.split(variable, 1)
ValueError: empty separator
Traceback (most recent call last):
  File "check_exec.py", line 166, in <module>
    main(sys.argv[i])
  File "check_exec.py", line 83, in main
    result = find_bounds_issues(line, argument)
  File "check_exec.py", line 94, in find_bounds_issues
    frontHalf, backHalf = line.split(variable, 1)
ValueError: empty separator
Traceback (most recent call last):
  File "check_exec.py", line 166, in <module>
    main(sys.argv[i])
  File "check_exec.py", line 83, in main
    result = find_bounds_issues(line, argument)
  File "check_exec.py", line 94, in find_bounds_issues
    frontHalf, backHalf = line.split(variable, 1)
ValueError: empty separator
Traceback (most recent call last):
  File "check_exec.py", line 166, in <module>
    main(sys.argv[i])
  File "check_exec.py", line 83, in main
    result = find_bounds_issues(line, argument)
  File "check_exec.py", line 94, in find_bounds_issues
    frontHalf, backHalf = line.split(variable, 1)
ValueError: empty separator
Traceback (most recent call last):
  File "check_exec.py", line 166, in <module>
    main(sys.argv[i])
  File "check_exec.py", line 33, in main
    for lineNum, line in enumerate(f):
  File "/usr/lib/python3.4/codecs.py", line 319, in decode
    (result, consumed) = self._buffer_decode(data, self.errors, final)
UnicodeDecodeError: 'utf-8' codec can't decode byte 0xac in position 919: invalid start byte
Traceback (most recent call last):
  File "check_exec.py", line 166, in <module>
    main(sys.argv[i])
  File "check_exec.py", line 83, in main
    result = find_bounds_issues(line, argument)
  File "check_exec.py", line 94, in find_bounds_issues
    frontHalf, backHalf = line.split(variable, 1)
ValueError: empty separator
Traceback (most recent call last):
  File "check_exec.py", line 166, in <module>
    main(sys.argv[i])
  File "check_exec.py", line 83, in main
    result = find_bounds_issues(line, argument)
  File "check_exec.py", line 94, in find_bounds_issues
    frontHalf, backHalf = line.split(variable, 1)
ValueError: empty separator
Traceback (most recent call last):
  File "check_exec.py", line 166, in <module>
    main(sys.argv[i])
  File "check_exec.py", line 33, in main
    for lineNum, line in enumerate(f):
  File "/usr/lib/python3.4/codecs.py", line 319, in decode
    (result, consumed) = self._buffer_decode(data, self.errors, final)
UnicodeDecodeError: 'utf-8' codec can't decode byte 0xe7 in position 119: invalid continuation byte
Traceback (most recent call last):
  File "check_exec.py", line 166, in <module>
    main(sys.argv[i])
  File "check_exec.py", line 83, in main
    result = find_bounds_issues(line, argument)
  File "check_exec.py", line 94, in find_bounds_issues
    frontHalf, backHalf = line.split(variable, 1)
ValueError: empty separator
Traceback (most recent call last):
  File "check_exec.py", line 166, in <module>
    main(sys.argv[i])
  File "check_exec.py", line 33, in main
    for lineNum, line in enumerate(f):
  File "/usr/lib/python3.4/codecs.py", line 319, in decode
    (result, consumed) = self._buffer_decode(data, self.errors, final)
UnicodeDecodeError: 'utf-8' codec can't decode byte 0xa9 in position 65: invalid start byte
Traceback (most recent call last):
  File "check_exec.py", line 166, in <module>
    main(sys.argv[i])
  File "check_exec.py", line 33, in main
    for lineNum, line in enumerate(f):
  File "/usr/lib/python3.4/codecs.py", line 319, in decode
    (result, consumed) = self._buffer_decode(data, self.errors, final)
UnicodeDecodeError: 'utf-8' codec can't decode byte 0xa9 in position 25: invalid start byte
Traceback (most recent call last):
  File "check_exec.py", line 166, in <module>
    main(sys.argv[i])
  File "check_exec.py", line 33, in main
    for lineNum, line in enumerate(f):
  File "/usr/lib/python3.4/codecs.py", line 319, in decode
    (result, consumed) = self._buffer_decode(data, self.errors, final)
UnicodeDecodeError: 'utf-8' codec can't decode byte 0xa9 in position 25: invalid start byte
Traceback (most recent call last):
  File "check_exec.py", line 166, in <module>
    main(sys.argv[i])
  File "check_exec.py", line 33, in main
    for lineNum, line in enumerate(f):
  File "/usr/lib/python3.4/codecs.py", line 319, in decode
    (result, consumed) = self._buffer_decode(data, self.errors, final)
UnicodeDecodeError: 'utf-8' codec can't decode byte 0xa9 in position 25: invalid start byte
Traceback (most recent call last):
  File "check_exec.py", line 166, in <module>
    main(sys.argv[i])
  File "check_exec.py", line 33, in main
    for lineNum, line in enumerate(f):
  File "/usr/lib/python3.4/codecs.py", line 319, in decode
    (result, consumed) = self._buffer_decode(data, self.errors, final)
UnicodeDecodeError: 'utf-8' codec can't decode byte 0xa9 in position 25: invalid start byte
Traceback (most recent call last):
  File "check_exec.py", line 166, in <module>
    main(sys.argv[i])
  File "check_exec.py", line 33, in main
    for lineNum, line in enumerate(f):
  File "/usr/lib/python3.4/codecs.py", line 319, in decode
    (result, consumed) = self._buffer_decode(data, self.errors, final)
UnicodeDecodeError: 'utf-8' codec can't decode byte 0xa9 in position 25: invalid start byte
Traceback (most recent call last):
  File "check_exec.py", line 166, in <module>
    main(sys.argv[i])
  File "check_exec.py", line 33, in main
    for lineNum, line in enumerate(f):
  File "/usr/lib/python3.4/codecs.py", line 319, in decode
    (result, consumed) = self._buffer_decode(data, self.errors, final)
UnicodeDecodeError: 'utf-8' codec can't decode byte 0xa9 in position 25: invalid start byte
Traceback (most recent call last):
  File "check_exec.py", line 166, in <module>
    main(sys.argv[i])
  File "check_exec.py", line 33, in main
    for lineNum, line in enumerate(f):
  File "/usr/lib/python3.4/codecs.py", line 319, in decode
    (result, consumed) = self._buffer_decode(data, self.errors, final)
UnicodeDecodeError: 'utf-8' codec can't decode byte 0xa9 in position 25: invalid start byte
Traceback (most recent call last):
  File "check_exec.py", line 166, in <module>
    main(sys.argv[i])
  File "check_exec.py", line 33, in main
    for lineNum, line in enumerate(f):
  File "/usr/lib/python3.4/codecs.py", line 319, in decode
    (result, consumed) = self._buffer_decode(data, self.errors, final)
UnicodeDecodeError: 'utf-8' codec can't decode byte 0xa9 in position 25: invalid start byte
Traceback (most recent call last):
  File "check_exec.py", line 166, in <module>
    main(sys.argv[i])
  File "check_exec.py", line 33, in main
    for lineNum, line in enumerate(f):
  File "/usr/lib/python3.4/codecs.py", line 319, in decode
    (result, consumed) = self._buffer_decode(data, self.errors, final)
UnicodeDecodeError: 'utf-8' codec can't decode byte 0xa9 in position 25: invalid start byte
Traceback (most recent call last):
  File "check_exec.py", line 166, in <module>
    main(sys.argv[i])
  File "check_exec.py", line 33, in main
    for lineNum, line in enumerate(f):
  File "/usr/lib/python3.4/codecs.py", line 319, in decode
    (result, consumed) = self._buffer_decode(data, self.errors, final)
UnicodeDecodeError: 'utf-8' codec can't decode byte 0xa9 in position 25: invalid start byte
Traceback (most recent call last):
  File "check_exec.py", line 166, in <module>
    main(sys.argv[i])
  File "check_exec.py", line 33, in main
    for lineNum, line in enumerate(f):
  File "/usr/lib/python3.4/codecs.py", line 319, in decode
    (result, consumed) = self._buffer_decode(data, self.errors, final)
UnicodeDecodeError: 'utf-8' codec can't decode byte 0xa9 in position 25: invalid start byte
Traceback (most recent call last):
  File "check_exec.py", line 166, in <module>
    main(sys.argv[i])
  File "check_exec.py", line 33, in main
    for lineNum, line in enumerate(f):
  File "/usr/lib/python3.4/codecs.py", line 319, in decode
    (result, consumed) = self._buffer_decode(data, self.errors, final)
UnicodeDecodeError: 'utf-8' codec can't decode byte 0xa9 in position 25: invalid start byte
Traceback (most recent call last):
  File "check_exec.py", line 166, in <module>
    main(sys.argv[i])
  File "check_exec.py", line 33, in main
    for lineNum, line in enumerate(f):
  File "/usr/lib/python3.4/codecs.py", line 319, in decode
    (result, consumed) = self._buffer_decode(data, self.errors, final)
UnicodeDecodeError: 'utf-8' codec can't decode byte 0xa9 in position 25: invalid start byte
Traceback (most recent call last):
  File "check_exec.py", line 166, in <module>
    main(sys.argv[i])
  File "check_exec.py", line 33, in main
    for lineNum, line in enumerate(f):
  File "/usr/lib/python3.4/codecs.py", line 319, in decode
    (result, consumed) = self._buffer_decode(data, self.errors, final)
UnicodeDecodeError: 'utf-8' codec can't decode byte 0xa9 in position 25: invalid start byte
Traceback (most recent call last):
  File "check_exec.py", line 166, in <module>
    main(sys.argv[i])
  File "check_exec.py", line 33, in main
    for lineNum, line in enumerate(f):
  File "/usr/lib/python3.4/codecs.py", line 319, in decode
    (result, consumed) = self._buffer_decode(data, self.errors, final)
UnicodeDecodeError: 'utf-8' codec can't decode byte 0xa9 in position 25: invalid start byte
Traceback (most recent call last):
  File "check_exec.py", line 166, in <module>
    main(sys.argv[i])
  File "check_exec.py", line 33, in main
    for lineNum, line in enumerate(f):
  File "/usr/lib/python3.4/codecs.py", line 319, in decode
    (result, consumed) = self._buffer_decode(data, self.errors, final)
UnicodeDecodeError: 'utf-8' codec can't decode byte 0xa9 in position 25: invalid start byte
Traceback (most recent call last):
  File "check_exec.py", line 166, in <module>
    main(sys.argv[i])
  File "check_exec.py", line 33, in main
    for lineNum, line in enumerate(f):
  File "/usr/lib/python3.4/codecs.py", line 319, in decode
    (result, consumed) = self._buffer_decode(data, self.errors, final)
UnicodeDecodeError: 'utf-8' codec can't decode byte 0xa9 in position 25: invalid start byte
Traceback (most recent call last):
  File "check_exec.py", line 166, in <module>
    main(sys.argv[i])
  File "check_exec.py", line 33, in main
    for lineNum, line in enumerate(f):
  File "/usr/lib/python3.4/codecs.py", line 319, in decode
    (result, consumed) = self._buffer_decode(data, self.errors, final)
UnicodeDecodeError: 'utf-8' codec can't decode byte 0xa9 in position 25: invalid start byte
Traceback (most recent call last):
  File "check_exec.py", line 166, in <module>
    main(sys.argv[i])
  File "check_exec.py", line 33, in main
    for lineNum, line in enumerate(f):
  File "/usr/lib/python3.4/codecs.py", line 319, in decode
    (result, consumed) = self._buffer_decode(data, self.errors, final)
UnicodeDecodeError: 'utf-8' codec can't decode byte 0xa9 in position 25: invalid start byte
Traceback (most recent call last):
  File "check_exec.py", line 166, in <module>
    main(sys.argv[i])
  File "check_exec.py", line 33, in main
    for lineNum, line in enumerate(f):
  File "/usr/lib/python3.4/codecs.py", line 319, in decode
    (result, consumed) = self._buffer_decode(data, self.errors, final)
UnicodeDecodeError: 'utf-8' codec can't decode byte 0xa9 in position 25: invalid start byte
Traceback (most recent call last):
  File "check_exec.py", line 166, in <module>
    main(sys.argv[i])
  File "check_exec.py", line 33, in main
    for lineNum, line in enumerate(f):
  File "/usr/lib/python3.4/codecs.py", line 319, in decode
    (result, consumed) = self._buffer_decode(data, self.errors, final)
UnicodeDecodeError: 'utf-8' codec can't decode byte 0xa9 in position 25: invalid start byte
Traceback (most recent call last):
  File "check_exec.py", line 166, in <module>
    main(sys.argv[i])
  File "check_exec.py", line 33, in main
    for lineNum, line in enumerate(f):
  File "/usr/lib/python3.4/codecs.py", line 319, in decode
    (result, consumed) = self._buffer_decode(data, self.errors, final)
UnicodeDecodeError: 'utf-8' codec can't decode byte 0xa9 in position 25: invalid start byte
Traceback (most recent call last):
  File "check_exec.py", line 166, in <module>
    main(sys.argv[i])
  File "check_exec.py", line 33, in main
    for lineNum, line in enumerate(f):
  File "/usr/lib/python3.4/codecs.py", line 319, in decode
    (result, consumed) = self._buffer_decode(data, self.errors, final)
UnicodeDecodeError: 'utf-8' codec can't decode byte 0xa9 in position 25: invalid start byte
Traceback (most recent call last):
  File "check_exec.py", line 166, in <module>
    main(sys.argv[i])
  File "check_exec.py", line 33, in main
    for lineNum, line in enumerate(f):
  File "/usr/lib/python3.4/codecs.py", line 319, in decode
    (result, consumed) = self._buffer_decode(data, self.errors, final)
UnicodeDecodeError: 'utf-8' codec can't decode byte 0xa9 in position 25: invalid start byte
Traceback (most recent call last):
  File "check_exec.py", line 166, in <module>
    main(sys.argv[i])
  File "check_exec.py", line 83, in main
    result = find_bounds_issues(line, argument)
  File "check_exec.py", line 94, in find_bounds_issues
    frontHalf, backHalf = line.split(variable, 1)
ValueError: empty separator
Traceback (most recent call last):
  File "check_exec.py", line 166, in <module>
    main(sys.argv[i])
  File "check_exec.py", line 83, in main
    result = find_bounds_issues(line, argument)
  File "check_exec.py", line 94, in find_bounds_issues
    frontHalf, backHalf = line.split(variable, 1)
ValueError: empty separator
Traceback (most recent call last):
  File "check_exec.py", line 166, in <module>
    main(sys.argv[i])
  File "check_exec.py", line 83, in main
    result = find_bounds_issues(line, argument)
  File "check_exec.py", line 94, in find_bounds_issues
    frontHalf, backHalf = line.split(variable, 1)
ValueError: empty separator
Traceback (most recent call last):
  File "check_exec.py", line 166, in <module>
    main(sys.argv[i])
  File "check_exec.py", line 83, in main
    result = find_bounds_issues(line, argument)
  File "check_exec.py", line 94, in find_bounds_issues
    frontHalf, backHalf = line.split(variable, 1)
ValueError: empty separator
Traceback (most recent call last):
  File "check_exec.py", line 166, in <module>
    main(sys.argv[i])
  File "check_exec.py", line 83, in main
    result = find_bounds_issues(line, argument)
  File "check_exec.py", line 94, in find_bounds_issues
    frontHalf, backHalf = line.split(variable, 1)
ValueError: empty separator
Traceback (most recent call last):
  File "check_exec.py", line 166, in <module>
    main(sys.argv[i])
  File "check_exec.py", line 83, in main
    result = find_bounds_issues(line, argument)
  File "check_exec.py", line 94, in find_bounds_issues
    frontHalf, backHalf = line.split(variable, 1)
ValueError: empty separator
Traceback (most recent call last):
  File "check_exec.py", line 166, in <module>
    main(sys.argv[i])
  File "check_exec.py", line 83, in main
    result = find_bounds_issues(line, argument)
  File "check_exec.py", line 94, in find_bounds_issues
    frontHalf, backHalf = line.split(variable, 1)
ValueError: empty separator
Traceback (most recent call last):
  File "check_exec.py", line 166, in <module>
    main(sys.argv[i])
  File "check_exec.py", line 83, in main
    result = find_bounds_issues(line, argument)
  File "check_exec.py", line 94, in find_bounds_issues
    frontHalf, backHalf = line.split(variable, 1)
ValueError: empty separator
Traceback (most recent call last):
  File "check_exec.py", line 166, in <module>
    main(sys.argv[i])
  File "check_exec.py", line 83, in main
    result = find_bounds_issues(line, argument)
  File "check_exec.py", line 94, in find_bounds_issues
    frontHalf, backHalf = line.split(variable, 1)
ValueError: empty separator
Traceback (most recent call last):
  File "check_exec.py", line 166, in <module>
    main(sys.argv[i])
  File "check_exec.py", line 83, in main
    result = find_bounds_issues(line, argument)
  File "check_exec.py", line 94, in find_bounds_issues
    frontHalf, backHalf = line.split(variable, 1)
ValueError: empty separator
Traceback (most recent call last):
  File "check_exec.py", line 166, in <module>
    main(sys.argv[i])
  File "check_exec.py", line 83, in main
    result = find_bounds_issues(line, argument)
  File "check_exec.py", line 94, in find_bounds_issues
    frontHalf, backHalf = line.split(variable, 1)
ValueError: empty separator
Traceback (most recent call last):
  File "check_exec.py", line 166, in <module>
    main(sys.argv[i])
  File "check_exec.py", line 83, in main
    result = find_bounds_issues(line, argument)
  File "check_exec.py", line 94, in find_bounds_issues
    frontHalf, backHalf = line.split(variable, 1)
ValueError: empty separator
Traceback (most recent call last):
  File "check_exec.py", line 166, in <module>
    main(sys.argv[i])
  File "check_exec.py", line 83, in main
    result = find_bounds_issues(line, argument)
  File "check_exec.py", line 94, in find_bounds_issues
    frontHalf, backHalf = line.split(variable, 1)
ValueError: empty separator
Traceback (most recent call last):
  File "check_exec.py", line 166, in <module>
    main(sys.argv[i])
  File "check_exec.py", line 83, in main
    result = find_bounds_issues(line, argument)
  File "check_exec.py", line 94, in find_bounds_issues
    frontHalf, backHalf = line.split(variable, 1)
ValueError: empty separator
Traceback (most recent call last):
  File "check_exec.py", line 166, in <module>
    main(sys.argv[i])
  File "check_exec.py", line 83, in main
    result = find_bounds_issues(line, argument)
  File "check_exec.py", line 94, in find_bounds_issues
    frontHalf, backHalf = line.split(variable, 1)
ValueError: empty separator
Traceback (most recent call last):
  File "check_exec.py", line 166, in <module>
    main(sys.argv[i])
  File "check_exec.py", line 83, in main
    result = find_bounds_issues(line, argument)
  File "check_exec.py", line 94, in find_bounds_issues
    frontHalf, backHalf = line.split(variable, 1)
ValueError: empty separator
Traceback (most recent call last):
  File "check_exec.py", line 166, in <module>
    main(sys.argv[i])
  File "check_exec.py", line 83, in main
    result = find_bounds_issues(line, argument)
  File "check_exec.py", line 94, in find_bounds_issues
    frontHalf, backHalf = line.split(variable, 1)
ValueError: empty separator
Traceback (most recent call last):
  File "check_exec.py", line 166, in <module>
    main(sys.argv[i])
  File "check_exec.py", line 83, in main
    result = find_bounds_issues(line, argument)
  File "check_exec.py", line 94, in find_bounds_issues
    frontHalf, backHalf = line.split(variable, 1)
ValueError: empty separator
Traceback (most recent call last):
  File "check_exec.py", line 166, in <module>
    main(sys.argv[i])
  File "check_exec.py", line 33, in main
    for lineNum, line in enumerate(f):
  File "/usr/lib/python3.4/codecs.py", line 319, in decode
    (result, consumed) = self._buffer_decode(data, self.errors, final)
UnicodeDecodeError: 'utf-8' codec can't decode byte 0xa1 in position 1925: invalid start byte
Traceback (most recent call last):
  File "check_exec.py", line 166, in <module>
    main(sys.argv[i])
  File "check_exec.py", line 83, in main
    result = find_bounds_issues(line, argument)
  File "check_exec.py", line 94, in find_bounds_issues
    frontHalf, backHalf = line.split(variable, 1)
ValueError: empty separator
Traceback (most recent call last):
  File "check_exec.py", line 166, in <module>
    main(sys.argv[i])
  File "check_exec.py", line 83, in main
    result = find_bounds_issues(line, argument)
  File "check_exec.py", line 94, in find_bounds_issues
    frontHalf, backHalf = line.split(variable, 1)
ValueError: empty separator
Traceback (most recent call last):
  File "check_exec.py", line 166, in <module>
    main(sys.argv[i])
  File "check_exec.py", line 83, in main
    result = find_bounds_issues(line, argument)
  File "check_exec.py", line 94, in find_bounds_issues
    frontHalf, backHalf = line.split(variable, 1)
ValueError: empty separator
Traceback (most recent call last):
  File "check_exec.py", line 166, in <module>
    main(sys.argv[i])
  File "check_exec.py", line 33, in main
    for lineNum, line in enumerate(f):
  File "/usr/lib/python3.4/codecs.py", line 319, in decode
    (result, consumed) = self._buffer_decode(data, self.errors, final)
UnicodeDecodeError: 'utf-8' codec can't decode byte 0xa0 in position 2329: invalid start byte
Traceback (most recent call last):
  File "check_exec.py", line 166, in <module>
    main(sys.argv[i])
  File "check_exec.py", line 33, in main
    for lineNum, line in enumerate(f):
  File "/usr/lib/python3.4/codecs.py", line 319, in decode
    (result, consumed) = self._buffer_decode(data, self.errors, final)
UnicodeDecodeError: 'utf-8' codec can't decode byte 0xa9 in position 1070: invalid start byte
Traceback (most recent call last):
  File "check_exec.py", line 166, in <module>
    main(sys.argv[i])
  File "check_exec.py", line 33, in main
    for lineNum, line in enumerate(f):
  File "/usr/lib/python3.4/codecs.py", line 319, in decode
    (result, consumed) = self._buffer_decode(data, self.errors, final)
UnicodeDecodeError: 'utf-8' codec can't decode byte 0xa9 in position 1069: invalid start byte
Traceback (most recent call last):
  File "check_exec.py", line 166, in <module>
    main(sys.argv[i])
  File "check_exec.py", line 33, in main
    for lineNum, line in enumerate(f):
  File "/usr/lib/python3.4/codecs.py", line 319, in decode
    (result, consumed) = self._buffer_decode(data, self.errors, final)
UnicodeDecodeError: 'utf-8' codec can't decode byte 0xa9 in position 1048: invalid start byte
Traceback (most recent call last):
  File "check_exec.py", line 166, in <module>
    main(sys.argv[i])
  File "check_exec.py", line 33, in main
    for lineNum, line in enumerate(f):
  File "/usr/lib/python3.4/codecs.py", line 319, in decode
    (result, consumed) = self._buffer_decode(data, self.errors, final)
UnicodeDecodeError: 'utf-8' codec can't decode byte 0xa9 in position 1076: invalid start byte
Traceback (most recent call last):
  File "check_exec.py", line 166, in <module>
    main(sys.argv[i])
  File "check_exec.py", line 33, in main
    for lineNum, line in enumerate(f):
  File "/usr/lib/python3.4/codecs.py", line 319, in decode
    (result, consumed) = self._buffer_decode(data, self.errors, final)
UnicodeDecodeError: 'utf-8' codec can't decode byte 0xa9 in position 1096: invalid start byte
Traceback (most recent call last):
  File "check_exec.py", line 166, in <module>
    main(sys.argv[i])
  File "check_exec.py", line 33, in main
    for lineNum, line in enumerate(f):
  File "/usr/lib/python3.4/codecs.py", line 319, in decode
    (result, consumed) = self._buffer_decode(data, self.errors, final)
UnicodeDecodeError: 'utf-8' codec can't decode byte 0xa9 in position 1113: invalid start byte
Traceback (most recent call last):
  File "check_exec.py", line 166, in <module>
    main(sys.argv[i])
  File "check_exec.py", line 33, in main
    for lineNum, line in enumerate(f):
  File "/usr/lib/python3.4/codecs.py", line 319, in decode
    (result, consumed) = self._buffer_decode(data, self.errors, final)
UnicodeDecodeError: 'utf-8' codec can't decode byte 0xa9 in position 1128: invalid start byte
Traceback (most recent call last):
  File "check_exec.py", line 166, in <module>
    main(sys.argv[i])
  File "check_exec.py", line 33, in main
    for lineNum, line in enumerate(f):
  File "/usr/lib/python3.4/codecs.py", line 319, in decode
    (result, consumed) = self._buffer_decode(data, self.errors, final)
UnicodeDecodeError: 'utf-8' codec can't decode byte 0xa9 in position 1137: invalid start byte
Traceback (most recent call last):
  File "check_exec.py", line 166, in <module>
    main(sys.argv[i])
  File "check_exec.py", line 33, in main
    for lineNum, line in enumerate(f):
  File "/usr/lib/python3.4/codecs.py", line 319, in decode
    (result, consumed) = self._buffer_decode(data, self.errors, final)
UnicodeDecodeError: 'utf-8' codec can't decode byte 0xa9 in position 1130: invalid start byte
Traceback (most recent call last):
  File "check_exec.py", line 166, in <module>
    main(sys.argv[i])
  File "check_exec.py", line 33, in main
    for lineNum, line in enumerate(f):
  File "/usr/lib/python3.4/codecs.py", line 319, in decode
    (result, consumed) = self._buffer_decode(data, self.errors, final)
UnicodeDecodeError: 'utf-8' codec can't decode byte 0xa9 in position 1132: invalid start byte
Traceback (most recent call last):
  File "check_exec.py", line 166, in <module>
    main(sys.argv[i])
  File "check_exec.py", line 33, in main
    for lineNum, line in enumerate(f):
  File "/usr/lib/python3.4/codecs.py", line 319, in decode
    (result, consumed) = self._buffer_decode(data, self.errors, final)
UnicodeDecodeError: 'utf-8' codec can't decode byte 0xa9 in position 1067: invalid start byte
Traceback (most recent call last):
  File "check_exec.py", line 166, in <module>
    main(sys.argv[i])
  File "check_exec.py", line 33, in main
    for lineNum, line in enumerate(f):
  File "/usr/lib/python3.4/codecs.py", line 319, in decode
    (result, consumed) = self._buffer_decode(data, self.errors, final)
UnicodeDecodeError: 'utf-8' codec can't decode byte 0xa9 in position 1045: invalid start byte
Traceback (most recent call last):
  File "check_exec.py", line 166, in <module>
    main(sys.argv[i])
  File "check_exec.py", line 33, in main
    for lineNum, line in enumerate(f):
  File "/usr/lib/python3.4/codecs.py", line 319, in decode
    (result, consumed) = self._buffer_decode(data, self.errors, final)
UnicodeDecodeError: 'utf-8' codec can't decode byte 0xa9 in position 1035: invalid start byte
Traceback (most recent call last):
  File "check_exec.py", line 166, in <module>
    main(sys.argv[i])
  File "check_exec.py", line 33, in main
    for lineNum, line in enumerate(f):
  File "/usr/lib/python3.4/codecs.py", line 319, in decode
    (result, consumed) = self._buffer_decode(data, self.errors, final)
UnicodeDecodeError: 'utf-8' codec can't decode byte 0xa9 in position 1055: invalid start byte
Traceback (most recent call last):
  File "check_exec.py", line 166, in <module>
    main(sys.argv[i])
  File "check_exec.py", line 83, in main
    result = find_bounds_issues(line, argument)
  File "check_exec.py", line 94, in find_bounds_issues
    frontHalf, backHalf = line.split(variable, 1)
ValueError: empty separator
Traceback (most recent call last):
  File "check_exec.py", line 166, in <module>
    main(sys.argv[i])
  File "check_exec.py", line 33, in main
    for lineNum, line in enumerate(f):
  File "/usr/lib/python3.4/codecs.py", line 319, in decode
    (result, consumed) = self._buffer_decode(data, self.errors, final)
UnicodeDecodeError: 'utf-8' codec can't decode byte 0xc4 in position 7417: invalid continuation byte
Traceback (most recent call last):
  File "check_exec.py", line 166, in <module>
    main(sys.argv[i])
  File "check_exec.py", line 83, in main
    result = find_bounds_issues(line, argument)
  File "check_exec.py", line 94, in find_bounds_issues
    frontHalf, backHalf = line.split(variable, 1)
ValueError: empty separator
Traceback (most recent call last):
  File "check_exec.py", line 166, in <module>
    main(sys.argv[i])
  File "check_exec.py", line 83, in main
    result = find_bounds_issues(line, argument)
  File "check_exec.py", line 94, in find_bounds_issues
    frontHalf, backHalf = line.split(variable, 1)
ValueError: empty separator
Traceback (most recent call last):
  File "check_exec.py", line 166, in <module>
    main(sys.argv[i])
  File "check_exec.py", line 83, in main
    result = find_bounds_issues(line, argument)
  File "check_exec.py", line 94, in find_bounds_issues
    frontHalf, backHalf = line.split(variable, 1)
ValueError: empty separator
Traceback (most recent call last):
  File "check_exec.py", line 166, in <module>
    main(sys.argv[i])
  File "check_exec.py", line 83, in main
    result = find_bounds_issues(line, argument)
  File "check_exec.py", line 94, in find_bounds_issues
    frontHalf, backHalf = line.split(variable, 1)
ValueError: empty separator
Traceback (most recent call last):
  File "check_exec.py", line 166, in <module>
    main(sys.argv[i])
  File "check_exec.py", line 83, in main
    result = find_bounds_issues(line, argument)
  File "check_exec.py", line 94, in find_bounds_issues
    frontHalf, backHalf = line.split(variable, 1)
ValueError: empty separator
Traceback (most recent call last):
  File "check_exec.py", line 166, in <module>
    main(sys.argv[i])
  File "check_exec.py", line 83, in main
    result = find_bounds_issues(line, argument)
  File "check_exec.py", line 94, in find_bounds_issues
    frontHalf, backHalf = line.split(variable, 1)
ValueError: empty separator
Traceback (most recent call last):
  File "check_exec.py", line 166, in <module>
    main(sys.argv[i])
  File "check_exec.py", line 83, in main
    result = find_bounds_issues(line, argument)
  File "check_exec.py", line 94, in find_bounds_issues
    frontHalf, backHalf = line.split(variable, 1)
ValueError: empty separator
Traceback (most recent call last):
  File "check_exec.py", line 166, in <module>
    main(sys.argv[i])
  File "check_exec.py", line 83, in main
    result = find_bounds_issues(line, argument)
  File "check_exec.py", line 94, in find_bounds_issues
    frontHalf, backHalf = line.split(variable, 1)
ValueError: empty separator
Traceback (most recent call last):
  File "check_exec.py", line 166, in <module>
    main(sys.argv[i])
  File "check_exec.py", line 33, in main
    for lineNum, line in enumerate(f):
  File "/usr/lib/python3.4/codecs.py", line 319, in decode
    (result, consumed) = self._buffer_decode(data, self.errors, final)
UnicodeDecodeError: 'utf-8' codec can't decode byte 0xa4 in position 2537: invalid start byte
Traceback (most recent call last):
  File "check_exec.py", line 166, in <module>
    main(sys.argv[i])
  File "check_exec.py", line 33, in main
    for lineNum, line in enumerate(f):
  File "/usr/lib/python3.4/codecs.py", line 319, in decode
    (result, consumed) = self._buffer_decode(data, self.errors, final)
UnicodeDecodeError: 'utf-8' codec can't decode byte 0xa9 in position 1210: invalid start byte
Traceback (most recent call last):
  File "check_exec.py", line 166, in <module>
    main(sys.argv[i])
  File "check_exec.py", line 33, in main
    for lineNum, line in enumerate(f):
  File "/usr/lib/python3.4/codecs.py", line 319, in decode
    (result, consumed) = self._buffer_decode(data, self.errors, final)
UnicodeDecodeError: 'utf-8' codec can't decode byte 0xa9 in position 1061: invalid start byte
Traceback (most recent call last):
  File "check_exec.py", line 166, in <module>
    main(sys.argv[i])
  File "check_exec.py", line 33, in main
    for lineNum, line in enumerate(f):
  File "/usr/lib/python3.4/codecs.py", line 319, in decode
    (result, consumed) = self._buffer_decode(data, self.errors, final)
UnicodeDecodeError: 'utf-8' codec can't decode byte 0xa9 in position 1060: invalid start byte
Traceback (most recent call last):
  File "check_exec.py", line 166, in <module>
    main(sys.argv[i])
  File "check_exec.py", line 33, in main
    for lineNum, line in enumerate(f):
  File "/usr/lib/python3.4/codecs.py", line 319, in decode
    (result, consumed) = self._buffer_decode(data, self.errors, final)
UnicodeDecodeError: 'utf-8' codec can't decode byte 0xa9 in position 1059: invalid start byte
Traceback (most recent call last):
  File "check_exec.py", line 166, in <module>
    main(sys.argv[i])
  File "check_exec.py", line 33, in main
    for lineNum, line in enumerate(f):
  File "/usr/lib/python3.4/codecs.py", line 319, in decode
    (result, consumed) = self._buffer_decode(data, self.errors, final)
UnicodeDecodeError: 'utf-8' codec can't decode byte 0xa9 in position 1062: invalid start byte
Traceback (most recent call last):
  File "check_exec.py", line 166, in <module>
    main(sys.argv[i])
  File "check_exec.py", line 33, in main
    for lineNum, line in enumerate(f):
  File "/usr/lib/python3.4/codecs.py", line 319, in decode
    (result, consumed) = self._buffer_decode(data, self.errors, final)
UnicodeDecodeError: 'utf-8' codec can't decode byte 0xa9 in position 1050: invalid start byte
Traceback (most recent call last):
  File "check_exec.py", line 166, in <module>
    main(sys.argv[i])
  File "check_exec.py", line 33, in main
    for lineNum, line in enumerate(f):
  File "/usr/lib/python3.4/codecs.py", line 319, in decode
    (result, consumed) = self._buffer_decode(data, self.errors, final)
UnicodeDecodeError: 'utf-8' codec can't decode byte 0xa9 in position 1056: invalid start byte
Traceback (most recent call last):
  File "check_exec.py", line 166, in <module>
    main(sys.argv[i])
  File "check_exec.py", line 33, in main
    for lineNum, line in enumerate(f):
  File "/usr/lib/python3.4/codecs.py", line 319, in decode
    (result, consumed) = self._buffer_decode(data, self.errors, final)
UnicodeDecodeError: 'utf-8' codec can't decode byte 0xa9 in position 1051: invalid start byte
Traceback (most recent call last):
  File "check_exec.py", line 166, in <module>
    main(sys.argv[i])
  File "check_exec.py", line 33, in main
    for lineNum, line in enumerate(f):
  File "/usr/lib/python3.4/codecs.py", line 319, in decode
    (result, consumed) = self._buffer_decode(data, self.errors, final)
UnicodeDecodeError: 'utf-8' codec can't decode byte 0xa9 in position 1064: invalid start byte
Traceback (most recent call last):
  File "check_exec.py", line 166, in <module>
    main(sys.argv[i])
  File "check_exec.py", line 33, in main
    for lineNum, line in enumerate(f):
  File "/usr/lib/python3.4/codecs.py", line 319, in decode
    (result, consumed) = self._buffer_decode(data, self.errors, final)
UnicodeDecodeError: 'utf-8' codec can't decode byte 0xa9 in position 1058: invalid start byte
Traceback (most recent call last):
  File "check_exec.py", line 166, in <module>
    main(sys.argv[i])
  File "check_exec.py", line 33, in main
    for lineNum, line in enumerate(f):
  File "/usr/lib/python3.4/codecs.py", line 319, in decode
    (result, consumed) = self._buffer_decode(data, self.errors, final)
UnicodeDecodeError: 'utf-8' codec can't decode byte 0xa9 in position 1061: invalid start byte
Traceback (most recent call last):
  File "check_exec.py", line 166, in <module>
    main(sys.argv[i])
  File "check_exec.py", line 33, in main
    for lineNum, line in enumerate(f):
  File "/usr/lib/python3.4/codecs.py", line 319, in decode
    (result, consumed) = self._buffer_decode(data, self.errors, final)
UnicodeDecodeError: 'utf-8' codec can't decode byte 0xa9 in position 1059: invalid start byte
Traceback (most recent call last):
  File "check_exec.py", line 166, in <module>
    main(sys.argv[i])
  File "check_exec.py", line 33, in main
    for lineNum, line in enumerate(f):
  File "/usr/lib/python3.4/codecs.py", line 319, in decode
    (result, consumed) = self._buffer_decode(data, self.errors, final)
UnicodeDecodeError: 'utf-8' codec can't decode byte 0xa9 in position 1061: invalid start byte
Traceback (most recent call last):
  File "check_exec.py", line 166, in <module>
    main(sys.argv[i])
  File "check_exec.py", line 33, in main
    for lineNum, line in enumerate(f):
  File "/usr/lib/python3.4/codecs.py", line 319, in decode
    (result, consumed) = self._buffer_decode(data, self.errors, final)
UnicodeDecodeError: 'utf-8' codec can't decode byte 0xa9 in position 1053: invalid start byte
Traceback (most recent call last):
  File "check_exec.py", line 166, in <module>
    main(sys.argv[i])
  File "check_exec.py", line 33, in main
    for lineNum, line in enumerate(f):
  File "/usr/lib/python3.4/codecs.py", line 319, in decode
    (result, consumed) = self._buffer_decode(data, self.errors, final)
UnicodeDecodeError: 'utf-8' codec can't decode byte 0xa9 in position 1062: invalid start byte
Traceback (most recent call last):
  File "check_exec.py", line 166, in <module>
    main(sys.argv[i])
  File "check_exec.py", line 33, in main
    for lineNum, line in enumerate(f):
  File "/usr/lib/python3.4/codecs.py", line 319, in decode
    (result, consumed) = self._buffer_decode(data, self.errors, final)
UnicodeDecodeError: 'utf-8' codec can't decode byte 0xa9 in position 1055: invalid start byte
Traceback (most recent call last):
  File "check_exec.py", line 166, in <module>
    main(sys.argv[i])
  File "check_exec.py", line 33, in main
    for lineNum, line in enumerate(f):
  File "/usr/lib/python3.4/codecs.py", line 319, in decode
    (result, consumed) = self._buffer_decode(data, self.errors, final)
UnicodeDecodeError: 'utf-8' codec can't decode byte 0xa9 in position 1060: invalid start byte
Traceback (most recent call last):
  File "check_exec.py", line 166, in <module>
    main(sys.argv[i])
  File "check_exec.py", line 33, in main
    for lineNum, line in enumerate(f):
  File "/usr/lib/python3.4/codecs.py", line 319, in decode
    (result, consumed) = self._buffer_decode(data, self.errors, final)
UnicodeDecodeError: 'utf-8' codec can't decode byte 0xa9 in position 1061: invalid start byte
Traceback (most recent call last):
  File "check_exec.py", line 166, in <module>
    main(sys.argv[i])
  File "check_exec.py", line 33, in main
    for lineNum, line in enumerate(f):
  File "/usr/lib/python3.4/codecs.py", line 319, in decode
    (result, consumed) = self._buffer_decode(data, self.errors, final)
UnicodeDecodeError: 'utf-8' codec can't decode byte 0xa9 in position 1056: invalid start byte
Traceback (most recent call last):
  File "check_exec.py", line 166, in <module>
    main(sys.argv[i])
  File "check_exec.py", line 33, in main
    for lineNum, line in enumerate(f):
  File "/usr/lib/python3.4/codecs.py", line 319, in decode
    (result, consumed) = self._buffer_decode(data, self.errors, final)
UnicodeDecodeError: 'utf-8' codec can't decode byte 0xa9 in position 1063: invalid start byte
Traceback (most recent call last):
  File "check_exec.py", line 166, in <module>
    main(sys.argv[i])
  File "check_exec.py", line 33, in main
    for lineNum, line in enumerate(f):
  File "/usr/lib/python3.4/codecs.py", line 319, in decode
    (result, consumed) = self._buffer_decode(data, self.errors, final)
UnicodeDecodeError: 'utf-8' codec can't decode byte 0xa9 in position 1052: invalid start byte
Traceback (most recent call last):
  File "check_exec.py", line 166, in <module>
    main(sys.argv[i])
  File "check_exec.py", line 33, in main
    for lineNum, line in enumerate(f):
  File "/usr/lib/python3.4/codecs.py", line 319, in decode
    (result, consumed) = self._buffer_decode(data, self.errors, final)
UnicodeDecodeError: 'utf-8' codec can't decode byte 0xa9 in position 1061: invalid start byte
Traceback (most recent call last):
  File "check_exec.py", line 166, in <module>
    main(sys.argv[i])
  File "check_exec.py", line 33, in main
    for lineNum, line in enumerate(f):
  File "/usr/lib/python3.4/codecs.py", line 319, in decode
    (result, consumed) = self._buffer_decode(data, self.errors, final)
UnicodeDecodeError: 'utf-8' codec can't decode byte 0xa9 in position 1050: invalid start byte
Traceback (most recent call last):
  File "check_exec.py", line 166, in <module>
    main(sys.argv[i])
  File "check_exec.py", line 33, in main
    for lineNum, line in enumerate(f):
  File "/usr/lib/python3.4/codecs.py", line 319, in decode
    (result, consumed) = self._buffer_decode(data, self.errors, final)
UnicodeDecodeError: 'utf-8' codec can't decode byte 0xa9 in position 1051: invalid start byte
Traceback (most recent call last):
  File "check_exec.py", line 166, in <module>
    main(sys.argv[i])
  File "check_exec.py", line 33, in main
    for lineNum, line in enumerate(f):
  File "/usr/lib/python3.4/codecs.py", line 319, in decode
    (result, consumed) = self._buffer_decode(data, self.errors, final)
UnicodeDecodeError: 'utf-8' codec can't decode byte 0xa9 in position 1050: invalid start byte
Traceback (most recent call last):
  File "check_exec.py", line 166, in <module>
    main(sys.argv[i])
  File "check_exec.py", line 33, in main
    for lineNum, line in enumerate(f):
  File "/usr/lib/python3.4/codecs.py", line 319, in decode
    (result, consumed) = self._buffer_decode(data, self.errors, final)
UnicodeDecodeError: 'utf-8' codec can't decode byte 0xa9 in position 1060: invalid start byte
Traceback (most recent call last):
  File "check_exec.py", line 166, in <module>
    main(sys.argv[i])
  File "check_exec.py", line 33, in main
    for lineNum, line in enumerate(f):
  File "/usr/lib/python3.4/codecs.py", line 319, in decode
    (result, consumed) = self._buffer_decode(data, self.errors, final)
UnicodeDecodeError: 'utf-8' codec can't decode byte 0xa9 in position 1058: invalid start byte
Traceback (most recent call last):
  File "check_exec.py", line 166, in <module>
    main(sys.argv[i])
  File "check_exec.py", line 33, in main
    for lineNum, line in enumerate(f):
  File "/usr/lib/python3.4/codecs.py", line 319, in decode
    (result, consumed) = self._buffer_decode(data, self.errors, final)
UnicodeDecodeError: 'utf-8' codec can't decode byte 0xa9 in position 1056: invalid start byte
Traceback (most recent call last):
  File "check_exec.py", line 166, in <module>
    main(sys.argv[i])
  File "check_exec.py", line 33, in main
    for lineNum, line in enumerate(f):
  File "/usr/lib/python3.4/codecs.py", line 319, in decode
    (result, consumed) = self._buffer_decode(data, self.errors, final)
UnicodeDecodeError: 'utf-8' codec can't decode byte 0xa9 in position 1043: invalid start byte
Traceback (most recent call last):
  File "check_exec.py", line 166, in <module>
    main(sys.argv[i])
  File "check_exec.py", line 33, in main
    for lineNum, line in enumerate(f):
  File "/usr/lib/python3.4/codecs.py", line 319, in decode
    (result, consumed) = self._buffer_decode(data, self.errors, final)
UnicodeDecodeError: 'utf-8' codec can't decode byte 0xa9 in position 1058: invalid start byte
Traceback (most recent call last):
  File "check_exec.py", line 166, in <module>
    main(sys.argv[i])
  File "check_exec.py", line 33, in main
    for lineNum, line in enumerate(f):
  File "/usr/lib/python3.4/codecs.py", line 319, in decode
    (result, consumed) = self._buffer_decode(data, self.errors, final)
UnicodeDecodeError: 'utf-8' codec can't decode byte 0xa9 in position 1055: invalid start byte
Traceback (most recent call last):
  File "check_exec.py", line 166, in <module>
    main(sys.argv[i])
  File "check_exec.py", line 33, in main
    for lineNum, line in enumerate(f):
  File "/usr/lib/python3.4/codecs.py", line 319, in decode
    (result, consumed) = self._buffer_decode(data, self.errors, final)
UnicodeDecodeError: 'utf-8' codec can't decode byte 0xa9 in position 1054: invalid start byte
Traceback (most recent call last):
  File "check_exec.py", line 166, in <module>
    main(sys.argv[i])
  File "check_exec.py", line 33, in main
    for lineNum, line in enumerate(f):
  File "/usr/lib/python3.4/codecs.py", line 319, in decode
    (result, consumed) = self._buffer_decode(data, self.errors, final)
UnicodeDecodeError: 'utf-8' codec can't decode byte 0xa9 in position 1053: invalid start byte
Traceback (most recent call last):
  File "check_exec.py", line 166, in <module>
    main(sys.argv[i])
  File "check_exec.py", line 33, in main
    for lineNum, line in enumerate(f):
  File "/usr/lib/python3.4/codecs.py", line 319, in decode
    (result, consumed) = self._buffer_decode(data, self.errors, final)
UnicodeDecodeError: 'utf-8' codec can't decode byte 0xa9 in position 1053: invalid start byte
Traceback (most recent call last):
  File "check_exec.py", line 166, in <module>
    main(sys.argv[i])
  File "check_exec.py", line 33, in main
    for lineNum, line in enumerate(f):
  File "/usr/lib/python3.4/codecs.py", line 319, in decode
    (result, consumed) = self._buffer_decode(data, self.errors, final)
UnicodeDecodeError: 'utf-8' codec can't decode byte 0xa9 in position 1058: invalid start byte
Traceback (most recent call last):
  File "check_exec.py", line 166, in <module>
    main(sys.argv[i])
  File "check_exec.py", line 33, in main
    for lineNum, line in enumerate(f):
  File "/usr/lib/python3.4/codecs.py", line 319, in decode
    (result, consumed) = self._buffer_decode(data, self.errors, final)
UnicodeDecodeError: 'utf-8' codec can't decode byte 0xa9 in position 1062: invalid start byte
Traceback (most recent call last):
  File "check_exec.py", line 166, in <module>
    main(sys.argv[i])
  File "check_exec.py", line 33, in main
    for lineNum, line in enumerate(f):
  File "/usr/lib/python3.4/codecs.py", line 319, in decode
    (result, consumed) = self._buffer_decode(data, self.errors, final)
UnicodeDecodeError: 'utf-8' codec can't decode byte 0xa9 in position 1060: invalid start byte
Traceback (most recent call last):
  File "check_exec.py", line 166, in <module>
    main(sys.argv[i])
  File "check_exec.py", line 83, in main
    result = find_bounds_issues(line, argument)
  File "check_exec.py", line 94, in find_bounds_issues
    frontHalf, backHalf = line.split(variable, 1)
ValueError: empty separator
Traceback (most recent call last):
  File "check_exec.py", line 166, in <module>
    main(sys.argv[i])
  File "check_exec.py", line 83, in main
    result = find_bounds_issues(line, argument)
  File "check_exec.py", line 94, in find_bounds_issues
    frontHalf, backHalf = line.split(variable, 1)
ValueError: empty separator
Traceback (most recent call last):
  File "check_exec.py", line 166, in <module>
    main(sys.argv[i])
  File "check_exec.py", line 83, in main
    result = find_bounds_issues(line, argument)
  File "check_exec.py", line 94, in find_bounds_issues
    frontHalf, backHalf = line.split(variable, 1)
ValueError: empty separator
Traceback (most recent call last):
  File "check_exec.py", line 166, in <module>
    main(sys.argv[i])
  File "check_exec.py", line 83, in main
    result = find_bounds_issues(line, argument)
  File "check_exec.py", line 94, in find_bounds_issues
    frontHalf, backHalf = line.split(variable, 1)
ValueError: empty separator
Traceback (most recent call last):
  File "check_exec.py", line 166, in <module>
    main(sys.argv[i])
  File "check_exec.py", line 83, in main
    result = find_bounds_issues(line, argument)
  File "check_exec.py", line 94, in find_bounds_issues
    frontHalf, backHalf = line.split(variable, 1)
ValueError: empty separator
Traceback (most recent call last):
  File "check_exec.py", line 166, in <module>
    main(sys.argv[i])
  File "check_exec.py", line 83, in main
    result = find_bounds_issues(line, argument)
  File "check_exec.py", line 94, in find_bounds_issues
    frontHalf, backHalf = line.split(variable, 1)
ValueError: empty separator
Traceback (most recent call last):
  File "check_exec.py", line 166, in <module>
    main(sys.argv[i])
  File "check_exec.py", line 83, in main
    result = find_bounds_issues(line, argument)
  File "check_exec.py", line 94, in find_bounds_issues
    frontHalf, backHalf = line.split(variable, 1)
ValueError: empty separator
Traceback (most recent call last):
  File "check_exec.py", line 166, in <module>
    main(sys.argv[i])
  File "check_exec.py", line 83, in main
    result = find_bounds_issues(line, argument)
  File "check_exec.py", line 94, in find_bounds_issues
    frontHalf, backHalf = line.split(variable, 1)
ValueError: empty separator
Traceback (most recent call last):
  File "check_exec.py", line 166, in <module>
    main(sys.argv[i])
  File "check_exec.py", line 83, in main
    result = find_bounds_issues(line, argument)
  File "check_exec.py", line 94, in find_bounds_issues
    frontHalf, backHalf = line.split(variable, 1)
ValueError: empty separator
Traceback (most recent call last):
  File "check_exec.py", line 166, in <module>
    main(sys.argv[i])
  File "check_exec.py", line 83, in main
    result = find_bounds_issues(line, argument)
  File "check_exec.py", line 94, in find_bounds_issues
    frontHalf, backHalf = line.split(variable, 1)
ValueError: empty separator
Traceback (most recent call last):
  File "check_exec.py", line 166, in <module>
    main(sys.argv[i])
  File "check_exec.py", line 83, in main
    result = find_bounds_issues(line, argument)
  File "check_exec.py", line 94, in find_bounds_issues
    frontHalf, backHalf = line.split(variable, 1)
ValueError: empty separator
Traceback (most recent call last):
  File "check_exec.py", line 166, in <module>
    main(sys.argv[i])
  File "check_exec.py", line 83, in main
    result = find_bounds_issues(line, argument)
  File "check_exec.py", line 94, in find_bounds_issues
    frontHalf, backHalf = line.split(variable, 1)
ValueError: empty separator
Traceback (most recent call last):
  File "check_exec.py", line 166, in <module>
    main(sys.argv[i])
  File "check_exec.py", line 83, in main
    result = find_bounds_issues(line, argument)
  File "check_exec.py", line 94, in find_bounds_issues
    frontHalf, backHalf = line.split(variable, 1)
ValueError: empty separator
Traceback (most recent call last):
  File "check_exec.py", line 166, in <module>
    main(sys.argv[i])
  File "check_exec.py", line 83, in main
    result = find_bounds_issues(line, argument)
  File "check_exec.py", line 94, in find_bounds_issues
    frontHalf, backHalf = line.split(variable, 1)
ValueError: empty separator
Traceback (most recent call last):
  File "check_exec.py", line 166, in <module>
    main(sys.argv[i])
  File "check_exec.py", line 33, in main
    for lineNum, line in enumerate(f):
  File "/usr/lib/python3.4/codecs.py", line 319, in decode
    (result, consumed) = self._buffer_decode(data, self.errors, final)
UnicodeDecodeError: 'utf-8' codec can't decode byte 0xe6 in position 1011: invalid continuation byte
Traceback (most recent call last):
  File "check_exec.py", line 166, in <module>
    main(sys.argv[i])
  File "check_exec.py", line 33, in main
    for lineNum, line in enumerate(f):
  File "/usr/lib/python3.4/codecs.py", line 319, in decode
    (result, consumed) = self._buffer_decode(data, self.errors, final)
UnicodeDecodeError: 'utf-8' codec can't decode byte 0xe6 in position 1011: invalid continuation byte
Traceback (most recent call last):
  File "check_exec.py", line 166, in <module>
    main(sys.argv[i])
  File "check_exec.py", line 33, in main
    for lineNum, line in enumerate(f):
  File "/usr/lib/python3.4/codecs.py", line 319, in decode
    (result, consumed) = self._buffer_decode(data, self.errors, final)
UnicodeDecodeError: 'utf-8' codec can't decode byte 0xe6 in position 1087: invalid continuation byte
Traceback (most recent call last):
  File "check_exec.py", line 166, in <module>
    main(sys.argv[i])
  File "check_exec.py", line 33, in main
    for lineNum, line in enumerate(f):
  File "/usr/lib/python3.4/codecs.py", line 319, in decode
    (result, consumed) = self._buffer_decode(data, self.errors, final)
UnicodeDecodeError: 'utf-8' codec can't decode byte 0xe4 in position 1016: invalid continuation byte
Traceback (most recent call last):
  File "check_exec.py", line 166, in <module>
    main(sys.argv[i])
  File "check_exec.py", line 83, in main
    result = find_bounds_issues(line, argument)
  File "check_exec.py", line 94, in find_bounds_issues
    frontHalf, backHalf = line.split(variable, 1)
ValueError: empty separator
Traceback (most recent call last):
  File "check_exec.py", line 166, in <module>
    main(sys.argv[i])
  File "check_exec.py", line 33, in main
    for lineNum, line in enumerate(f):
  File "/usr/lib/python3.4/codecs.py", line 319, in decode
    (result, consumed) = self._buffer_decode(data, self.errors, final)
UnicodeDecodeError: 'utf-8' codec can't decode byte 0xf8 in position 1006: invalid start byte
Traceback (most recent call last):
  File "check_exec.py", line 166, in <module>
    main(sys.argv[i])
  File "check_exec.py", line 33, in main
    for lineNum, line in enumerate(f):
  File "/usr/lib/python3.4/codecs.py", line 319, in decode
    (result, consumed) = self._buffer_decode(data, self.errors, final)
UnicodeDecodeError: 'utf-8' codec can't decode byte 0xe6 in position 1011: invalid continuation byte
Traceback (most recent call last):
  File "check_exec.py", line 166, in <module>
    main(sys.argv[i])
  File "check_exec.py", line 33, in main
    for lineNum, line in enumerate(f):
  File "/usr/lib/python3.4/codecs.py", line 319, in decode
    (result, consumed) = self._buffer_decode(data, self.errors, final)
UnicodeDecodeError: 'utf-8' codec can't decode byte 0xe6 in position 1010: invalid continuation byte
Traceback (most recent call last):
  File "check_exec.py", line 166, in <module>
    main(sys.argv[i])
  File "check_exec.py", line 33, in main
    for lineNum, line in enumerate(f):
  File "/usr/lib/python3.4/codecs.py", line 319, in decode
    (result, consumed) = self._buffer_decode(data, self.errors, final)
UnicodeDecodeError: 'utf-8' codec can't decode byte 0xe6 in position 1011: invalid continuation byte
Traceback (most recent call last):
  File "check_exec.py", line 166, in <module>
    main(sys.argv[i])
  File "check_exec.py", line 33, in main
    for lineNum, line in enumerate(f):
  File "/usr/lib/python3.4/codecs.py", line 319, in decode
    (result, consumed) = self._buffer_decode(data, self.errors, final)
UnicodeDecodeError: 'utf-8' codec can't decode byte 0xe4 in position 1091: invalid continuation byte
Traceback (most recent call last):
  File "check_exec.py", line 166, in <module>
    main(sys.argv[i])
  File "check_exec.py", line 33, in main
    for lineNum, line in enumerate(f):
  File "/usr/lib/python3.4/codecs.py", line 319, in decode
    (result, consumed) = self._buffer_decode(data, self.errors, final)
UnicodeDecodeError: 'utf-8' codec can't decode byte 0xe6 in position 1087: invalid continuation byte
Traceback (most recent call last):
  File "check_exec.py", line 166, in <module>
    main(sys.argv[i])
  File "check_exec.py", line 33, in main
    for lineNum, line in enumerate(f):
  File "/usr/lib/python3.4/codecs.py", line 319, in decode
    (result, consumed) = self._buffer_decode(data, self.errors, final)
UnicodeDecodeError: 'utf-8' codec can't decode byte 0xe4 in position 1167: invalid continuation byte
Traceback (most recent call last):
  File "check_exec.py", line 166, in <module>
    main(sys.argv[i])
  File "check_exec.py", line 33, in main
    for lineNum, line in enumerate(f):
  File "/usr/lib/python3.4/codecs.py", line 319, in decode
    (result, consumed) = self._buffer_decode(data, self.errors, final)
UnicodeDecodeError: 'utf-8' codec can't decode byte 0xe6 in position 1011: invalid continuation byte
Traceback (most recent call last):
  File "check_exec.py", line 166, in <module>
    main(sys.argv[i])
  File "check_exec.py", line 33, in main
    for lineNum, line in enumerate(f):
  File "/usr/lib/python3.4/codecs.py", line 319, in decode
    (result, consumed) = self._buffer_decode(data, self.errors, final)
UnicodeDecodeError: 'utf-8' codec can't decode byte 0xe9 in position 1239: invalid continuation byte
Traceback (most recent call last):
  File "check_exec.py", line 166, in <module>
    main(sys.argv[i])
  File "check_exec.py", line 83, in main
    result = find_bounds_issues(line, argument)
  File "check_exec.py", line 94, in find_bounds_issues
    frontHalf, backHalf = line.split(variable, 1)
ValueError: empty separator
Traceback (most recent call last):
  File "check_exec.py", line 166, in <module>
    main(sys.argv[i])
  File "check_exec.py", line 33, in main
    for lineNum, line in enumerate(f):
  File "/usr/lib/python3.4/codecs.py", line 319, in decode
    (result, consumed) = self._buffer_decode(data, self.errors, final)
UnicodeDecodeError: 'utf-8' codec can't decode byte 0xf6 in position 1089: invalid start byte
Traceback (most recent call last):
  File "check_exec.py", line 166, in <module>
    main(sys.argv[i])
  File "check_exec.py", line 83, in main
    result = find_bounds_issues(line, argument)
  File "check_exec.py", line 94, in find_bounds_issues
    frontHalf, backHalf = line.split(variable, 1)
ValueError: empty separator
Traceback (most recent call last):
  File "check_exec.py", line 166, in <module>
    main(sys.argv[i])
  File "check_exec.py", line 83, in main
    result = find_bounds_issues(line, argument)
  File "check_exec.py", line 94, in find_bounds_issues
    frontHalf, backHalf = line.split(variable, 1)
ValueError: empty separator
Traceback (most recent call last):
  File "check_exec.py", line 166, in <module>
    main(sys.argv[i])
  File "check_exec.py", line 83, in main
    result = find_bounds_issues(line, argument)
  File "check_exec.py", line 94, in find_bounds_issues
    frontHalf, backHalf = line.split(variable, 1)
ValueError: empty separator
Traceback (most recent call last):
  File "check_exec.py", line 166, in <module>
    main(sys.argv[i])
  File "check_exec.py", line 33, in main
    for lineNum, line in enumerate(f):
  File "/usr/lib/python3.4/codecs.py", line 319, in decode
    (result, consumed) = self._buffer_decode(data, self.errors, final)
UnicodeDecodeError: 'utf-8' codec can't decode byte 0xe6 in position 1011: invalid continuation byte
Traceback (most recent call last):
  File "check_exec.py", line 166, in <module>
    main(sys.argv[i])
  File "check_exec.py", line 33, in main
    for lineNum, line in enumerate(f):
  File "/usr/lib/python3.4/codecs.py", line 319, in decode
    (result, consumed) = self._buffer_decode(data, self.errors, final)
UnicodeDecodeError: 'utf-8' codec can't decode byte 0xe6 in position 1011: invalid continuation byte
Traceback (most recent call last):
  File "check_exec.py", line 166, in <module>
    main(sys.argv[i])
  File "check_exec.py", line 33, in main
    for lineNum, line in enumerate(f):
  File "/usr/lib/python3.4/codecs.py", line 319, in decode
    (result, consumed) = self._buffer_decode(data, self.errors, final)
UnicodeDecodeError: 'utf-8' codec can't decode byte 0xe4 in position 1016: invalid continuation byte
Traceback (most recent call last):
  File "check_exec.py", line 166, in <module>
    main(sys.argv[i])
  File "check_exec.py", line 33, in main
    for lineNum, line in enumerate(f):
  File "/usr/lib/python3.4/codecs.py", line 319, in decode
    (result, consumed) = self._buffer_decode(data, self.errors, final)
UnicodeDecodeError: 'utf-8' codec can't decode byte 0xe6 in position 1087: invalid continuation byte
Traceback (most recent call last):
  File "check_exec.py", line 166, in <module>
    main(sys.argv[i])
  File "check_exec.py", line 33, in main
    for lineNum, line in enumerate(f):
  File "/usr/lib/python3.4/codecs.py", line 319, in decode
    (result, consumed) = self._buffer_decode(data, self.errors, final)
UnicodeDecodeError: 'utf-8' codec can't decode byte 0xe4 in position 83: invalid continuation byte
Traceback (most recent call last):
  File "check_exec.py", line 166, in <module>
    main(sys.argv[i])
  File "check_exec.py", line 83, in main
    result = find_bounds_issues(line, argument)
  File "check_exec.py", line 94, in find_bounds_issues
    frontHalf, backHalf = line.split(variable, 1)
ValueError: empty separator
Traceback (most recent call last):
  File "check_exec.py", line 166, in <module>
    main(sys.argv[i])
  File "check_exec.py", line 83, in main
    result = find_bounds_issues(line, argument)
  File "check_exec.py", line 94, in find_bounds_issues
    frontHalf, backHalf = line.split(variable, 1)
ValueError: empty separator
Traceback (most recent call last):
  File "check_exec.py", line 166, in <module>
    main(sys.argv[i])
  File "check_exec.py", line 83, in main
    result = find_bounds_issues(line, argument)
  File "check_exec.py", line 94, in find_bounds_issues
    frontHalf, backHalf = line.split(variable, 1)
ValueError: empty separator
Traceback (most recent call last):
  File "check_exec.py", line 166, in <module>
    main(sys.argv[i])
  File "check_exec.py", line 83, in main
    result = find_bounds_issues(line, argument)
  File "check_exec.py", line 94, in find_bounds_issues
    frontHalf, backHalf = line.split(variable, 1)
ValueError: empty separator
Traceback (most recent call last):
  File "check_exec.py", line 166, in <module>
    main(sys.argv[i])
  File "check_exec.py", line 33, in main
    for lineNum, line in enumerate(f):
  File "/usr/lib/python3.4/codecs.py", line 319, in decode
    (result, consumed) = self._buffer_decode(data, self.errors, final)
UnicodeDecodeError: 'utf-8' codec can't decode byte 0xa8 in position 5250: invalid start byte
Traceback (most recent call last):
  File "check_exec.py", line 166, in <module>
    main(sys.argv[i])
  File "check_exec.py", line 33, in main
    for lineNum, line in enumerate(f):
  File "/usr/lib/python3.4/codecs.py", line 319, in decode
    (result, consumed) = self._buffer_decode(data, self.errors, final)
UnicodeDecodeError: 'utf-8' codec can't decode byte 0xa9 in position 1000: invalid start byte
Traceback (most recent call last):
  File "check_exec.py", line 166, in <module>
    main(sys.argv[i])
  File "check_exec.py", line 83, in main
    result = find_bounds_issues(line, argument)
  File "check_exec.py", line 94, in find_bounds_issues
    frontHalf, backHalf = line.split(variable, 1)
ValueError: empty separator
Traceback (most recent call last):
  File "check_exec.py", line 166, in <module>
    main(sys.argv[i])
  File "check_exec.py", line 83, in main
    result = find_bounds_issues(line, argument)
  File "check_exec.py", line 94, in find_bounds_issues
    frontHalf, backHalf = line.split(variable, 1)
ValueError: empty separator
Traceback (most recent call last):
  File "check_exec.py", line 166, in <module>
    main(sys.argv[i])
  File "check_exec.py", line 83, in main
    result = find_bounds_issues(line, argument)
  File "check_exec.py", line 94, in find_bounds_issues
    frontHalf, backHalf = line.split(variable, 1)
ValueError: empty separator
Traceback (most recent call last):
  File "check_exec.py", line 166, in <module>
    main(sys.argv[i])
  File "check_exec.py", line 83, in main
    result = find_bounds_issues(line, argument)
  File "check_exec.py", line 94, in find_bounds_issues
    frontHalf, backHalf = line.split(variable, 1)
ValueError: empty separator
Traceback (most recent call last):
  File "check_exec.py", line 166, in <module>
    main(sys.argv[i])
  File "check_exec.py", line 83, in main
    result = find_bounds_issues(line, argument)
  File "check_exec.py", line 94, in find_bounds_issues
    frontHalf, backHalf = line.split(variable, 1)
ValueError: empty separator
Traceback (most recent call last):
  File "check_exec.py", line 166, in <module>
    main(sys.argv[i])
  File "check_exec.py", line 83, in main
    result = find_bounds_issues(line, argument)
  File "check_exec.py", line 94, in find_bounds_issues
    frontHalf, backHalf = line.split(variable, 1)
ValueError: empty separator
Traceback (most recent call last):
  File "check_exec.py", line 166, in <module>
    main(sys.argv[i])
  File "check_exec.py", line 83, in main
    result = find_bounds_issues(line, argument)
  File "check_exec.py", line 94, in find_bounds_issues
    frontHalf, backHalf = line.split(variable, 1)
ValueError: empty separator
Traceback (most recent call last):
  File "check_exec.py", line 166, in <module>
    main(sys.argv[i])
  File "check_exec.py", line 83, in main
    result = find_bounds_issues(line, argument)
  File "check_exec.py", line 94, in find_bounds_issues
    frontHalf, backHalf = line.split(variable, 1)
ValueError: empty separator
Traceback (most recent call last):
  File "check_exec.py", line 166, in <module>
    main(sys.argv[i])
  File "check_exec.py", line 33, in main
    for lineNum, line in enumerate(f):
  File "/usr/lib/python3.4/codecs.py", line 319, in decode
    (result, consumed) = self._buffer_decode(data, self.errors, final)
UnicodeDecodeError: 'utf-8' codec can't decode byte 0xa5 in position 3565: invalid start byte
Traceback (most recent call last):
  File "check_exec.py", line 166, in <module>
    main(sys.argv[i])
  File "check_exec.py", line 33, in main
    for lineNum, line in enumerate(f):
  File "/usr/lib/python3.4/codecs.py", line 319, in decode
    (result, consumed) = self._buffer_decode(data, self.errors, final)
UnicodeDecodeError: 'utf-8' codec can't decode byte 0xca in position 1241: invalid continuation byte
Traceback (most recent call last):
  File "check_exec.py", line 166, in <module>
    main(sys.argv[i])
  File "check_exec.py", line 33, in main
    for lineNum, line in enumerate(f):
  File "/usr/lib/python3.4/codecs.py", line 319, in decode
    (result, consumed) = self._buffer_decode(data, self.errors, final)
UnicodeDecodeError: 'utf-8' codec can't decode byte 0x8c in position 4886: invalid start byte
Traceback (most recent call last):
  File "check_exec.py", line 166, in <module>
    main(sys.argv[i])
  File "check_exec.py", line 33, in main
    for lineNum, line in enumerate(f):
  File "/usr/lib/python3.4/codecs.py", line 319, in decode
    (result, consumed) = self._buffer_decode(data, self.errors, final)
UnicodeDecodeError: 'utf-8' codec can't decode byte 0xca in position 3594: invalid continuation byte
Traceback (most recent call last):
  File "check_exec.py", line 166, in <module>
    main(sys.argv[i])
  File "check_exec.py", line 33, in main
    for lineNum, line in enumerate(f):
  File "/usr/lib/python3.4/codecs.py", line 319, in decode
    (result, consumed) = self._buffer_decode(data, self.errors, final)
UnicodeDecodeError: 'utf-8' codec can't decode byte 0xa5 in position 5211: invalid start byte
Traceback (most recent call last):
  File "check_exec.py", line 166, in <module>
    main(sys.argv[i])
  File "check_exec.py", line 33, in main
    for lineNum, line in enumerate(f):
  File "/usr/lib/python3.4/codecs.py", line 319, in decode
    (result, consumed) = self._buffer_decode(data, self.errors, final)
UnicodeDecodeError: 'utf-8' codec can't decode byte 0xca in position 994: invalid continuation byte
Traceback (most recent call last):
  File "check_exec.py", line 166, in <module>
    main(sys.argv[i])
  File "check_exec.py", line 83, in main
    result = find_bounds_issues(line, argument)
  File "check_exec.py", line 94, in find_bounds_issues
    frontHalf, backHalf = line.split(variable, 1)
ValueError: empty separator
Traceback (most recent call last):
  File "check_exec.py", line 166, in <module>
    main(sys.argv[i])
  File "check_exec.py", line 33, in main
    for lineNum, line in enumerate(f):
  File "/usr/lib/python3.4/codecs.py", line 319, in decode
    (result, consumed) = self._buffer_decode(data, self.errors, final)
UnicodeDecodeError: 'utf-8' codec can't decode byte 0xe4 in position 223: invalid continuation byte
Traceback (most recent call last):
  File "check_exec.py", line 166, in <module>
    main(sys.argv[i])
  File "check_exec.py", line 33, in main
    for lineNum, line in enumerate(f):
  File "/usr/lib/python3.4/codecs.py", line 319, in decode
    (result, consumed) = self._buffer_decode(data, self.errors, final)
UnicodeDecodeError: 'utf-8' codec can't decode byte 0xe4 in position 739: invalid continuation byte
Traceback (most recent call last):
  File "check_exec.py", line 166, in <module>
    main(sys.argv[i])
  File "check_exec.py", line 33, in main
    for lineNum, line in enumerate(f):
  File "/usr/lib/python3.4/codecs.py", line 319, in decode
    (result, consumed) = self._buffer_decode(data, self.errors, final)
UnicodeDecodeError: 'utf-8' codec can't decode byte 0xe4 in position 599: invalid continuation byte
Traceback (most recent call last):
  File "check_exec.py", line 166, in <module>
    main(sys.argv[i])
  File "check_exec.py", line 33, in main
    for lineNum, line in enumerate(f):
  File "/usr/lib/python3.4/codecs.py", line 319, in decode
    (result, consumed) = self._buffer_decode(data, self.errors, final)
UnicodeDecodeError: 'utf-8' codec can't decode byte 0xe4 in position 310: invalid continuation byte
Traceback (most recent call last):
  File "check_exec.py", line 166, in <module>
    main(sys.argv[i])
  File "check_exec.py", line 83, in main
    result = find_bounds_issues(line, argument)
  File "check_exec.py", line 94, in find_bounds_issues
    frontHalf, backHalf = line.split(variable, 1)
ValueError: empty separator
Traceback (most recent call last):
  File "check_exec.py", line 166, in <module>
    main(sys.argv[i])
  File "check_exec.py", line 33, in main
    for lineNum, line in enumerate(f):
  File "/usr/lib/python3.4/codecs.py", line 319, in decode
    (result, consumed) = self._buffer_decode(data, self.errors, final)
UnicodeDecodeError: 'utf-8' codec can't decode byte 0xe4 in position 273: invalid continuation byte
Traceback (most recent call last):
  File "check_exec.py", line 166, in <module>
    main(sys.argv[i])
  File "check_exec.py", line 33, in main
    for lineNum, line in enumerate(f):
  File "/usr/lib/python3.4/codecs.py", line 319, in decode
    (result, consumed) = self._buffer_decode(data, self.errors, final)
UnicodeDecodeError: 'utf-8' codec can't decode byte 0xe4 in position 625: invalid continuation byte
Traceback (most recent call last):
  File "check_exec.py", line 166, in <module>
    main(sys.argv[i])
  File "check_exec.py", line 33, in main
    for lineNum, line in enumerate(f):
  File "/usr/lib/python3.4/codecs.py", line 319, in decode
    (result, consumed) = self._buffer_decode(data, self.errors, final)
UnicodeDecodeError: 'utf-8' codec can't decode byte 0xe4 in position 282: invalid continuation byte
Traceback (most recent call last):
  File "check_exec.py", line 166, in <module>
    main(sys.argv[i])
  File "check_exec.py", line 33, in main
    for lineNum, line in enumerate(f):
  File "/usr/lib/python3.4/codecs.py", line 319, in decode
    (result, consumed) = self._buffer_decode(data, self.errors, final)
UnicodeDecodeError: 'utf-8' codec can't decode byte 0xe4 in position 337: invalid continuation byte
Traceback (most recent call last):
  File "check_exec.py", line 166, in <module>
    main(sys.argv[i])
  File "check_exec.py", line 33, in main
    for lineNum, line in enumerate(f):
  File "/usr/lib/python3.4/codecs.py", line 319, in decode
    (result, consumed) = self._buffer_decode(data, self.errors, final)
UnicodeDecodeError: 'utf-8' codec can't decode byte 0xe4 in position 549: invalid continuation byte
Traceback (most recent call last):
  File "check_exec.py", line 166, in <module>
    main(sys.argv[i])
  File "check_exec.py", line 33, in main
    for lineNum, line in enumerate(f):
  File "/usr/lib/python3.4/codecs.py", line 319, in decode
    (result, consumed) = self._buffer_decode(data, self.errors, final)
UnicodeDecodeError: 'utf-8' codec can't decode byte 0xe4 in position 304: invalid continuation byte
Traceback (most recent call last):
  File "check_exec.py", line 166, in <module>
    main(sys.argv[i])
  File "check_exec.py", line 33, in main
    for lineNum, line in enumerate(f):
  File "/usr/lib/python3.4/codecs.py", line 319, in decode
    (result, consumed) = self._buffer_decode(data, self.errors, final)
UnicodeDecodeError: 'utf-8' codec can't decode byte 0xe4 in position 306: invalid continuation byte
Traceback (most recent call last):
  File "check_exec.py", line 166, in <module>
    main(sys.argv[i])
  File "check_exec.py", line 33, in main
    for lineNum, line in enumerate(f):
  File "/usr/lib/python3.4/codecs.py", line 319, in decode
    (result, consumed) = self._buffer_decode(data, self.errors, final)
UnicodeDecodeError: 'utf-8' codec can't decode byte 0xe4 in position 555: invalid continuation byte
Traceback (most recent call last):
  File "check_exec.py", line 166, in <module>
    main(sys.argv[i])
  File "check_exec.py", line 33, in main
    for lineNum, line in enumerate(f):
  File "/usr/lib/python3.4/codecs.py", line 319, in decode
    (result, consumed) = self._buffer_decode(data, self.errors, final)
UnicodeDecodeError: 'utf-8' codec can't decode byte 0xe4 in position 395: invalid continuation byte
Traceback (most recent call last):
  File "check_exec.py", line 166, in <module>
    main(sys.argv[i])
  File "check_exec.py", line 83, in main
    result = find_bounds_issues(line, argument)
  File "check_exec.py", line 94, in find_bounds_issues
    frontHalf, backHalf = line.split(variable, 1)
ValueError: empty separator
Traceback (most recent call last):
  File "check_exec.py", line 166, in <module>
    main(sys.argv[i])
  File "check_exec.py", line 33, in main
    for lineNum, line in enumerate(f):
  File "/usr/lib/python3.4/codecs.py", line 319, in decode
    (result, consumed) = self._buffer_decode(data, self.errors, final)
UnicodeDecodeError: 'utf-8' codec can't decode byte 0xfd in position 6769: invalid start byte
Traceback (most recent call last):
  File "check_exec.py", line 166, in <module>
    main(sys.argv[i])
  File "check_exec.py", line 83, in main
    result = find_bounds_issues(line, argument)
  File "check_exec.py", line 94, in find_bounds_issues
    frontHalf, backHalf = line.split(variable, 1)
ValueError: empty separator
Traceback (most recent call last):
  File "check_exec.py", line 166, in <module>
    main(sys.argv[i])
  File "check_exec.py", line 83, in main
    result = find_bounds_issues(line, argument)
  File "check_exec.py", line 94, in find_bounds_issues
    frontHalf, backHalf = line.split(variable, 1)
ValueError: empty separator
Traceback (most recent call last):
  File "check_exec.py", line 166, in <module>
    main(sys.argv[i])
  File "check_exec.py", line 83, in main
    result = find_bounds_issues(line, argument)
  File "check_exec.py", line 94, in find_bounds_issues
    frontHalf, backHalf = line.split(variable, 1)
ValueError: empty separator
Traceback (most recent call last):
  File "check_exec.py", line 166, in <module>
    main(sys.argv[i])
  File "check_exec.py", line 83, in main
    result = find_bounds_issues(line, argument)
  File "check_exec.py", line 94, in find_bounds_issues
    frontHalf, backHalf = line.split(variable, 1)
ValueError: empty separator
Traceback (most recent call last):
  File "check_exec.py", line 166, in <module>
    main(sys.argv[i])
  File "check_exec.py", line 83, in main
    result = find_bounds_issues(line, argument)
  File "check_exec.py", line 94, in find_bounds_issues
    frontHalf, backHalf = line.split(variable, 1)
ValueError: empty separator
Traceback (most recent call last):
  File "check_exec.py", line 166, in <module>
    main(sys.argv[i])
  File "check_exec.py", line 83, in main
    result = find_bounds_issues(line, argument)
  File "check_exec.py", line 94, in find_bounds_issues
    frontHalf, backHalf = line.split(variable, 1)
ValueError: empty separator
Traceback (most recent call last):
  File "check_exec.py", line 166, in <module>
    main(sys.argv[i])
  File "check_exec.py", line 83, in main
    result = find_bounds_issues(line, argument)
  File "check_exec.py", line 94, in find_bounds_issues
    frontHalf, backHalf = line.split(variable, 1)
ValueError: empty separator
Traceback (most recent call last):
  File "check_exec.py", line 166, in <module>
    main(sys.argv[i])
  File "check_exec.py", line 83, in main
    result = find_bounds_issues(line, argument)
  File "check_exec.py", line 94, in find_bounds_issues
    frontHalf, backHalf = line.split(variable, 1)
ValueError: empty separator
Traceback (most recent call last):
  File "check_exec.py", line 166, in <module>
    main(sys.argv[i])
  File "check_exec.py", line 83, in main
    result = find_bounds_issues(line, argument)
  File "check_exec.py", line 94, in find_bounds_issues
    frontHalf, backHalf = line.split(variable, 1)
ValueError: empty separator
Traceback (most recent call last):
  File "check_exec.py", line 166, in <module>
    main(sys.argv[i])
  File "check_exec.py", line 83, in main
    result = find_bounds_issues(line, argument)
  File "check_exec.py", line 94, in find_bounds_issues
    frontHalf, backHalf = line.split(variable, 1)
ValueError: empty separator
Traceback (most recent call last):
  File "check_exec.py", line 166, in <module>
    main(sys.argv[i])
  File "check_exec.py", line 83, in main
    result = find_bounds_issues(line, argument)
  File "check_exec.py", line 94, in find_bounds_issues
    frontHalf, backHalf = line.split(variable, 1)
ValueError: empty separator
Traceback (most recent call last):
  File "check_exec.py", line 166, in <module>
    main(sys.argv[i])
  File "check_exec.py", line 33, in main
    for lineNum, line in enumerate(f):
  File "/usr/lib/python3.4/codecs.py", line 319, in decode
    (result, consumed) = self._buffer_decode(data, self.errors, final)
UnicodeDecodeError: 'utf-8' codec can't decode byte 0xe9 in position 1188: invalid continuation byte
Traceback (most recent call last):
  File "check_exec.py", line 166, in <module>
    main(sys.argv[i])
  File "check_exec.py", line 33, in main
    for lineNum, line in enumerate(f):
  File "/usr/lib/python3.4/codecs.py", line 319, in decode
    (result, consumed) = self._buffer_decode(data, self.errors, final)
UnicodeDecodeError: 'utf-8' codec can't decode byte 0x80 in position 935: invalid start byte
Traceback (most recent call last):
  File "check_exec.py", line 166, in <module>
    main(sys.argv[i])
  File "check_exec.py", line 33, in main
    for lineNum, line in enumerate(f):
  File "/usr/lib/python3.4/codecs.py", line 319, in decode
    (result, consumed) = self._buffer_decode(data, self.errors, final)
UnicodeDecodeError: 'utf-8' codec can't decode byte 0xa9 in position 1008: invalid start byte
Traceback (most recent call last):
  File "check_exec.py", line 166, in <module>
    main(sys.argv[i])
  File "check_exec.py", line 83, in main
    result = find_bounds_issues(line, argument)
  File "check_exec.py", line 94, in find_bounds_issues
    frontHalf, backHalf = line.split(variable, 1)
ValueError: empty separator
Traceback (most recent call last):
  File "check_exec.py", line 166, in <module>
    main(sys.argv[i])
  File "check_exec.py", line 83, in main
    result = find_bounds_issues(line, argument)
  File "check_exec.py", line 94, in find_bounds_issues
    frontHalf, backHalf = line.split(variable, 1)
ValueError: empty separator
Traceback (most recent call last):
  File "check_exec.py", line 166, in <module>
    main(sys.argv[i])
  File "check_exec.py", line 83, in main
    result = find_bounds_issues(line, argument)
  File "check_exec.py", line 94, in find_bounds_issues
    frontHalf, backHalf = line.split(variable, 1)
ValueError: empty separator
Traceback (most recent call last):
  File "check_exec.py", line 166, in <module>
    main(sys.argv[i])
  File "check_exec.py", line 83, in main
    result = find_bounds_issues(line, argument)
  File "check_exec.py", line 94, in find_bounds_issues
    frontHalf, backHalf = line.split(variable, 1)
ValueError: empty separator
Traceback (most recent call last):
  File "check_exec.py", line 166, in <module>
    main(sys.argv[i])
  File "check_exec.py", line 83, in main
    result = find_bounds_issues(line, argument)
  File "check_exec.py", line 94, in find_bounds_issues
    frontHalf, backHalf = line.split(variable, 1)
ValueError: empty separator
Traceback (most recent call last):
  File "check_exec.py", line 166, in <module>
    main(sys.argv[i])
  File "check_exec.py", line 83, in main
    result = find_bounds_issues(line, argument)
  File "check_exec.py", line 94, in find_bounds_issues
    frontHalf, backHalf = line.split(variable, 1)
ValueError: empty separator
Traceback (most recent call last):
  File "check_exec.py", line 166, in <module>
    main(sys.argv[i])
  File "check_exec.py", line 33, in main
    for lineNum, line in enumerate(f):
  File "/usr/lib/python3.4/codecs.py", line 319, in decode
    (result, consumed) = self._buffer_decode(data, self.errors, final)
UnicodeDecodeError: 'utf-8' codec can't decode byte 0xb1 in position 1052: invalid start byte
Traceback (most recent call last):
  File "check_exec.py", line 166, in <module>
    main(sys.argv[i])
  File "check_exec.py", line 33, in main
    for lineNum, line in enumerate(f):
  File "/usr/lib/python3.4/codecs.py", line 319, in decode
    (result, consumed) = self._buffer_decode(data, self.errors, final)
UnicodeDecodeError: 'utf-8' codec can't decode byte 0xb1 in position 1053: invalid start byte
Traceback (most recent call last):
  File "check_exec.py", line 166, in <module>
    main(sys.argv[i])
  File "check_exec.py", line 83, in main
    result = find_bounds_issues(line, argument)
  File "check_exec.py", line 94, in find_bounds_issues
    frontHalf, backHalf = line.split(variable, 1)
ValueError: empty separator
Traceback (most recent call last):
  File "check_exec.py", line 166, in <module>
    main(sys.argv[i])
  File "check_exec.py", line 33, in main
    for lineNum, line in enumerate(f):
  File "/usr/lib/python3.4/codecs.py", line 319, in decode
    (result, consumed) = self._buffer_decode(data, self.errors, final)
UnicodeDecodeError: 'utf-8' codec can't decode byte 0xa9 in position 114: invalid start byte
Traceback (most recent call last):
  File "check_exec.py", line 166, in <module>
    main(sys.argv[i])
  File "check_exec.py", line 83, in main
    result = find_bounds_issues(line, argument)
  File "check_exec.py", line 94, in find_bounds_issues
    frontHalf, backHalf = line.split(variable, 1)
ValueError: empty separator
Traceback (most recent call last):
  File "check_exec.py", line 166, in <module>
    main(sys.argv[i])
  File "check_exec.py", line 83, in main
    result = find_bounds_issues(line, argument)
  File "check_exec.py", line 94, in find_bounds_issues
    frontHalf, backHalf = line.split(variable, 1)
ValueError: empty separator
Traceback (most recent call last):
  File "check_exec.py", line 166, in <module>
    main(sys.argv[i])
  File "check_exec.py", line 83, in main
    result = find_bounds_issues(line, argument)
  File "check_exec.py", line 94, in find_bounds_issues
    frontHalf, backHalf = line.split(variable, 1)
ValueError: empty separator
Traceback (most recent call last):
  File "check_exec.py", line 166, in <module>
    main(sys.argv[i])
  File "check_exec.py", line 83, in main
    result = find_bounds_issues(line, argument)
  File "check_exec.py", line 94, in find_bounds_issues
    frontHalf, backHalf = line.split(variable, 1)
ValueError: empty separator
Traceback (most recent call last):
  File "check_exec.py", line 166, in <module>
    main(sys.argv[i])
  File "check_exec.py", line 83, in main
    result = find_bounds_issues(line, argument)
  File "check_exec.py", line 94, in find_bounds_issues
    frontHalf, backHalf = line.split(variable, 1)
ValueError: empty separator
Traceback (most recent call last):
  File "check_exec.py", line 166, in <module>
    main(sys.argv[i])
  File "check_exec.py", line 83, in main
    result = find_bounds_issues(line, argument)
  File "check_exec.py", line 94, in find_bounds_issues
    frontHalf, backHalf = line.split(variable, 1)
ValueError: empty separator
Traceback (most recent call last):
  File "check_exec.py", line 166, in <module>
    main(sys.argv[i])
  File "check_exec.py", line 83, in main
    result = find_bounds_issues(line, argument)
  File "check_exec.py", line 94, in find_bounds_issues
    frontHalf, backHalf = line.split(variable, 1)
ValueError: empty separator
Traceback (most recent call last):
  File "check_exec.py", line 166, in <module>
    main(sys.argv[i])
  File "check_exec.py", line 33, in main
    for lineNum, line in enumerate(f):
  File "/usr/lib/python3.4/codecs.py", line 319, in decode
    (result, consumed) = self._buffer_decode(data, self.errors, final)
UnicodeDecodeError: 'utf-8' codec can't decode byte 0xe4 in position 7788: invalid continuation byte
Traceback (most recent call last):
  File "check_exec.py", line 166, in <module>
    main(sys.argv[i])
  File "check_exec.py", line 83, in main
    result = find_bounds_issues(line, argument)
  File "check_exec.py", line 94, in find_bounds_issues
    frontHalf, backHalf = line.split(variable, 1)
ValueError: empty separator
Traceback (most recent call last):
  File "check_exec.py", line 166, in <module>
    main(sys.argv[i])
  File "check_exec.py", line 83, in main
    result = find_bounds_issues(line, argument)
  File "check_exec.py", line 94, in find_bounds_issues
    frontHalf, backHalf = line.split(variable, 1)
ValueError: empty separator
Traceback (most recent call last):
  File "check_exec.py", line 166, in <module>
    main(sys.argv[i])
  File "check_exec.py", line 83, in main
    result = find_bounds_issues(line, argument)
  File "check_exec.py", line 94, in find_bounds_issues
    frontHalf, backHalf = line.split(variable, 1)
ValueError: empty separator
Traceback (most recent call last):
  File "check_exec.py", line 166, in <module>
    main(sys.argv[i])
  File "check_exec.py", line 83, in main
    result = find_bounds_issues(line, argument)
  File "check_exec.py", line 94, in find_bounds_issues
    frontHalf, backHalf = line.split(variable, 1)
ValueError: empty separator
Traceback (most recent call last):
  File "check_exec.py", line 166, in <module>
    main(sys.argv[i])
  File "check_exec.py", line 83, in main
    result = find_bounds_issues(line, argument)
  File "check_exec.py", line 94, in find_bounds_issues
    frontHalf, backHalf = line.split(variable, 1)
ValueError: empty separator
Traceback (most recent call last):
  File "check_exec.py", line 166, in <module>
    main(sys.argv[i])
  File "check_exec.py", line 83, in main
    result = find_bounds_issues(line, argument)
  File "check_exec.py", line 94, in find_bounds_issues
    frontHalf, backHalf = line.split(variable, 1)
ValueError: empty separator
Traceback (most recent call last):
  File "check_exec.py", line 166, in <module>
    main(sys.argv[i])
  File "check_exec.py", line 83, in main
    result = find_bounds_issues(line, argument)
  File "check_exec.py", line 94, in find_bounds_issues
    frontHalf, backHalf = line.split(variable, 1)
ValueError: empty separator
Traceback (most recent call last):
  File "check_exec.py", line 166, in <module>
    main(sys.argv[i])
  File "check_exec.py", line 83, in main
    result = find_bounds_issues(line, argument)
  File "check_exec.py", line 94, in find_bounds_issues
    frontHalf, backHalf = line.split(variable, 1)
ValueError: empty separator
Traceback (most recent call last):
  File "check_exec.py", line 166, in <module>
    main(sys.argv[i])
  File "check_exec.py", line 83, in main
    result = find_bounds_issues(line, argument)
  File "check_exec.py", line 94, in find_bounds_issues
    frontHalf, backHalf = line.split(variable, 1)
ValueError: empty separator
